Workbook

Sheet Parametros
A1: PARAMETROS — Edita la columna B y toda la simulacion se actualiza
A2: Las celdas B4:B11 son referenciadas por formulas en la hoja Simulacion. No mover. Cambiar el valor y Excel recalcula todo automaticamente.
A3: Parametro | B3: VALOR | C3: Rango valido | D3: Que controla
A4: a1 (alpha1) | B4: 0.95 | C4: 0.01 – 0.99 | D4: Decaimiento de la DENDRITA. Cerca de 1 = olvida despacio = memoria larga → paso-bajo
A5: a2 (alpha2) | B5: 0.05 | C5: 0.01 – 0.99 | D5: Decaimiento del SOMA. Cerca de 0 = olvida rapido = memoria corta → paso-alto
A6: b1 (beta1) | B6: 0 | C6: -1.0 – 1.0 | D6: Acoplamiento soma→dendrita. 0 = el soma no influye en la dendrita
A7: b2 (beta2) | B7: -0.9 | C7: -1.0 – 0.0 | D7: Acoplamiento dendrita→soma. Negativo = la dendrita frena al soma (evita saturacion)
A8: g1 (gamma1) | B8: 0.5 | C8: 0.0 – 2.0 | D8: Reset dendrita: vd baja en g1 cada vez que sd_prev=1 (la neurona disparo antes)
A9: g2 (gamma2) | B9: 1 | C9: 0.0 – 2.0 | D9: Reset soma: vs baja en g2 cada vez que ss_prev=1
A10: v_th | B10: 1 | C10: 0.1 – 2.0 | D10: Umbral de disparo: sd=1 si vd >= v_th / ss=1 si vs >= v_th
A11: kappa | B11: 0.5 | C11: 0.0 – 1.0 | D11: Peso de mezcla salida: s_mix = kappa*sd + (1-kappa)*ss
A13: VERIFICACION DE ESTABILIDAD (Teorema 1) — formulas Excel que recalculan con los parametros
A14: Magnitud | B14: Resultado | C14: Formula | D14: Que significa
A15: Traza | B15: =B4+B5+B6*B7 | C15: =B4+B5+B6*B7 | D15: a1 + a2 + b1*b2 — suma de los terminos de decaimiento mas el producto de acoplamientos
A16: Discriminante | B16: =SQRT(B15^2-4*B4*B5) | C16: =SQRT(B15^2-4*B4*B5) | D16: sqrt(traza^2 - 4*a1*a2) — parte variable bajo la raiz del polinomio caracteristico
A17: Lambda 1 (dendrita) | B17: =(B15+B16)/2 | C17: =(B15+B16)/2 | D17: Autovalor 1 = (traza + disc)/2 — constante de tiempo de la DENDRITA (debe ser |λ|<1)
A18: Lambda 2 (soma) | B18: =(B15-B16)/2 | C18: =(B15-B16)/2 | D18: Autovalor 2 = (traza - disc)/2 — constante de tiempo del SOMA (debe ser |λ|<1)
A19: |Lambda 1| < 1 ? | B19: =IF(ABS(B17)<1,"ESTABLE","INESTABLE — ajusta los parametros") | C19: =IF(ABS(B17)<1,"ESTABLE","INESTABLE — ajusta los parametros") | D19: Si es INESTABLE, el potencial crecera sin limite y la red divergira
A20: |Lambda 2| < 1 ? | B20: =IF(ABS(B18)<1,"ESTABLE","INESTABLE — ajusta los parametros") | C20: =IF(ABS(B18)<1,"ESTABLE","INESTABLE — ajusta los parametros") | D20: Ambos autovalores deben cumplir esta condicion para garantizar convergencia

Sheet Datos
A1: electricity_sample.csv — 168 horas x 3 nodos reales UCI Electricity dataset
A2: Hora t | B2: Nodo 0 | C2: Nodo 1 | D2: Nodo 2
A3: 0 | B3: 0.002481 | C3: 0.079179 | D3: 0.049125
A4: 1 | B4: 0.036386 | C4: 0.032258 | D4: 0.041099
A5: 2 | B5: 0.017159 | C5: 0.02346 | D5: 0.015807
A6: 3 | B6: 0.010544 | C6: 0.002933 | D6: 0.013375
A7: 4 | B7: 0.010337 | C7: 0.008798 | D7: 0.051556
A8: 5 | B8: 0.008683 | C8: 0 | D8: 0.23249
A9: 6 | B9: 0.013852 | C9: 0 | D9: 0.521158
A10: 7 | B10: 0.006409 | C10: 0.290323 | D10: 0.536965
A11: 8 | B11: 0 | C11: 0.390029 | D11: 0.580739
A12: 9 | B12: 0.040728 | C12: 0.527859 | D12: 0.700875
A13: 10 | B13: 0.131073 | C13: 0.612903 | D13: 0.663911
A14: 11 | B14: 0.177796 | C14: 0.668622 | D14: 0.626459
... A170: 167 | B170: 0.344222 | C170: 0.404692 | D170: 0.146644

Sheet Simulacion
A1: SIMULACION TS-LIF — Formulas Excel reales. Cambia Parametros!B4:B11 y todo recalcula automaticamente.
A2: ENTRADA | C2: DENDRITA → vd[t] = a1·vd_prev + b1·vs_prev + (1−a1)·c[t] − g1·sd_prev | J2: SOMA → vs[t] = a2·vs_prev + b2·vd[t] + (1−a2)·c[t] − g2·ss_prev | Q2: SALIDA
A3: t hora | B3: c[t] consumo entrada | C3: a1 · vd_prev 0.95 × vd ant. | D3: b1 · vs_prev 0.00 × vs ant. | E3: (1−a1) · c 0.05 × entrada | F3: −g1 · sd_prev −0.5 × spike_d_prev | G3: =vd[t] SUMA 4 terminos | H3: sd[t] spike dendrita | J3: a2 · vs_prev 0.05 × vs ant. | K3: b2 · vd[t] −0.9 × vd nuevo | L3: (1−a2) · c 0.95 × entrada | M3: −g2 · ss_prev −1.0 × spike_s_prev | N3: =vs[t] SUMA 4 terminos | O3: ss[t] spike soma | Q3: s_mix[t] κ·sd+(1−κ)·ss
A4: Estado inicial → vd = 0 | vs = 0 | sd = 0 | ss = 0 | G4: 0 | H4: 0 | N4: 0 | O4: 0
A5: 0 | B5: =Datos!$B$3 | C5: =Parametros!$B$4*G4 | D5: =Parametros!$B$6*N4 | E5: =(1-Parametros!$B$4)*B5 | F5: =-Parametros!$B$8*H4 | G5: =C5+D5+E5+F5 | H5: =IF(G5>=Parametros!$B$10,1,0) | J5: =Parametros!$B$5*N4 | K5: =Parametros!$B$7*G5 | L5: =(1-Parametros!$B$5)*B5 | M5: =-Parametros!$B$9*O4 | N5: =J5+K5+L5+M5 | O5: =IF(N5>=Parametros!$B$10,1,0) | Q5: =Parametros!$B$11*H5+(1-Parametros!$B$11)*O5
A6: 1 | B6: =Datos!$B$4 | C6: =Parametros!$B$4*G5 | D6: =Parametros!$B$6*N5 | E6: =(1-Parametros!$B$4)*B6 | F6: =-Parametros!$B$8*H5 | G6: =C6+D6+E6+F6 | H6: =IF(G6>=Parametros!$B$10,1,0) | J6: =Parametros!$B$5*N5 | K6: =Parametros!$B$7*G6 | L6: =(1-Parametros!$B$5)*B6 | M6: =-Parametros!$B$9*O5 | N6: =J6+K6+L6+M6 | O6: =IF(N6>=Parametros!$B$10,1,0) | Q6: =Parametros!$B$11*H6+(1-Parametros!$B$11)*O6
A7: 2 | B7: =Datos!$B$5 | C7: =Parametros!$B$4*G6 | D7: =Parametros!$B$6*N6 | E7: =(1-Parametros!$B$4)*B7 | F7: =-Parametros!$B$8*H6 | G7: =C7+D7+E7+F7 | H7: =IF(G7>=Parametros!$B$10,1,0) | J7: =Parametros!$B$5*N6 | K7: =Parametros!$B$7*G7 | L7: =(1-Parametros!$B$5)*B7 | M7: =-Parametros!$B$9*O6 | N7: =J7+K7+L7+M7 | O7: =IF(N7>=Parametros!$B$10,1,0) | Q7: =Parametros!$B$11*H7+(1-Parametros!$B$11)*O7
A8: 3 | B8: =Datos!$B$6 | C8: =Parametros!$B$4*G7 | D8: =Parametros!$B$6*N7 | E8: =(1-Parametros!$B$4)*B8 | F8: =-Parametros!$B$8*H7 | G8: =C8+D8+E8+F8 | H8: =IF(G8>=Parametros!$B$10,1,0) | J8: =Parametros!$B$5*N7 | K8: =Parametros!$B$7*G8 | L8: =(1-Parametros!$B$5)*B8 | M8: =-Parametros!$B$9*O7 | N8: =J8+K8+L8+M8 | O8: =IF(N8>=Parametros!$B$10,1,0) | Q8: =Parametros!$B$11*H8+(1-Parametros!$B$11)*O8
A9: 4 | B9: =Datos!$B$7 | C9: =Parametros!$B$4*G8 | D9: =Parametros!$B$6*N8 | E9: =(1-Parametros!$B$4)*B9 | F9: =-Parametros!$B$8*H8 | G9: =C9+D9+E9+F9 | H9: =IF(G9>=Parametros!$B$10,1,0) | J9: =Parametros!$B$5*N8 | K9: =Parametros!$B$7*G9 | L9: =(1-Parametros!$B$5)*B9 | M9: =-Parametros!$B$9*O8 | N9: =J9+K9+L9+M9 | O9: =IF(N9>=Parametros!$B$10,1,0) | Q9: =Parametros!$B$11*H9+(1-Parametros!$B$11)*O9
A10: 5 | B10: =Datos!$B$8 | C10: =Parametros!$B$4*G9 | D10: =Parametros!$B$6*N9 | E10: =(1-Parametros!$B$4)*B10 | F10: =-Parametros!$B$8*H9 | G10: =C10+D10+E10+F10 | H10: =IF(G10>=Parametros!$B$10,1,0) | J10: =Parametros!$B$5*N9 | K10: =Parametros!$B$7*G10 | L10: =(1-Parametros!$B$5)*B10 | M10: =-Parametros!$B$9*O9 | N10: =J10+K10+L10+M10 | O10: =IF(N10>=Parametros!$B$10,1,0) | Q10: =Parametros!$B$11*H10+(1-Parametros!$B$11)*O10
A11: 6 | B11: =Datos!$B$9 | C11: =Parametros!$B$4*G10 | D11: =Parametros!$B$6*N10 | E11: =(1-Parametros!$B$4)*B11 | F11: =-Parametros!$B$8*H10 | G11: =C11+D11+E11+F11 | H11: =IF(G11>=Parametros!$B$10,1,0) | J11: =Parametros!$B$5*N10 | K11: =Parametros!$B$7*G11 | L11: =(1-Parametros!$B$5)*B11 | M11: =-Parametros!$B$9*O10 | N11: =J11+K11+L11+M11 | O11: =IF(N11>=Parametros!$B$10,1,0) | Q11: =Parametros!$B$11*H11+(1-Parametros!$B$11)*O11
A12: 7 | B12: =Datos!$B$10 | C12: =Parametros!$B$4*G11 | D12: =Parametros!$B$6*N11 | E12: =(1-Parametros!$B$4)*B12 | F12: =-Parametros!$B$8*H11 | G12: =C12+D12+E12+F12 | H12: =IF(G12>=Parametros!$B$10,1,0) | J12: =Parametros!$B$5*N11 | K12: =Parametros!$B$7*G12 | L12: =(1-Parametros!$B$5)*B12 | M12: =-Parametros!$B$9*O11 | N12: =J12+K12+L12+M12 | O12: =IF(N12>=Parametros!$B$10,1,0) | Q12: =Parametros!$B$11*H12+(1-Parametros!$B$11)*O12
A13: 8 | B13: =Datos!$B$11 | C13: =Parametros!$B$4*G12 | D13: =Parametros!$B$6*N12 | E13: =(1-Parametros!$B$4)*B13 | F13: =-Parametros!$B$8*H12 | G13: =C13+D13+E13+F13 | H13: =IF(G13>=Parametros!$B$10,1,0) | J13: =Parametros!$B$5*N12 | K13: =Parametros!$B$7*G13 | L13: =(1-Parametros!$B$5)*B13 | M13: =-Parametros!$B$9*O12 | N13: =J13+K13+L13+M13 | O13: =IF(N13>=Parametros!$B$10,1,0) | Q13: =Parametros!$B$11*H13+(1-Parametros!$B$11)*O13
A14: 9 | B14: =Datos!$B$12 | C14: =Parametros!$B$4*G13 | D14: =Parametros!$B$6*N13 | E14: =(1-Parametros!$B$4)*B14 | F14: =-Parametros!$B$8*H13 | G14: =C14+D14+E14+F14 | H14: =IF(G14>=Parametros!$B$10,1,0) | J14: =Parametros!$B$5*N13 | K14: =Parametros!$B$7*G14 | L14: =(1-Parametros!$B$5)*B14 | M14: =-Parametros!$B$9*O13 | N14: =J14+K14+L14+M14 | O14: =IF(N14>=Parametros!$B$10,1,0) | Q14: =Parametros!$B$11*H14+(1-Parametros!$B$11)*O14
A15: 10 | B15: =Datos!$B$13 | C15: =Parametros!$B$4*G14 | D15: =Parametros!$B$6*N14 | E15: =(1-Parametros!$B$4)*B15 | F15: =-Parametros!$B$8*H14 | G15: =C15+D15+E15+F15 | H15: =IF(G15>=Parametros!$B$10,1,0) | J15: =Parametros!$B$5*N14 | K15: =Parametros!$B$7*G15 | L15: =(1-Parametros!$B$5)*B15 | M15: =-Parametros!$B$9*O14 | N15: =J15+K15+L15+M15 | O15: =IF(N15>=Parametros!$B$10,1,0) | Q15: =Parametros!$B$11*H15+(1-Parametros!$B$11)*O15
A16: 11 | B16: =Datos!$B$14 | C16: =Parametros!$B$4*G15 | D16: =Parametros!$B$6*N15 | E16: =(1-Parametros!$B$4)*B16 | F16: =-Parametros!$B$8*H15 | G16: =C16+D16+E16+F16 | H16: =IF(G16>=Parametros!$B$10,1,0) | J16: =Parametros!$B$5*N15 | K16: =Parametros!$B$7*G16 | L16: =(1-Parametros!$B$5)*B16 | M16: =-Parametros!$B$9*O15 | N16: =J16+K16+L16+M16 | O16: =IF(N16>=Parametros!$B$10,1,0) | Q16: =Parametros!$B$11*H16+(1-Parametros!$B$11)*O16
A17: 12 | B17: =Datos!$B$15 | C17: =Parametros!$B$4*G16 | D17: =Parametros!$B$6*N16 | E17: =(1-Parametros!$B$4)*B17 | F17: =-Parametros!$B$8*H16 | G17: =C17+D17+E17+F17 | H17: =IF(G17>=Parametros!$B$10,1,0) | J17: =Parametros!$B$5*N16 | K17: =Parametros!$B$7*G17 | L17: =(1-Parametros!$B$5)*B17 | M17: =-Parametros!$B$9*O16 | N17: =J17+K17+L17+M17 | O17: =IF(N17>=Parametros!$B$10,1,0) | Q17: =Parametros!$B$11*H17+(1-Parametros!$B$11)*O17
A18: 13 | B18: =Datos!$B$16 | C18: =Parametros!$B$4*G17 | D18: =Parametros!$B$6*N17 | E18: =(1-Parametros!$B$4)*B18 | F18: =-Parametros!$B$8*H17 | G18: =C18+D18+E18+F18 | H18: =IF(G18>=Parametros!$B$10,1,0) | J18: =Parametros!$B$5*N17 | K18: =Parametros!$B$7*G18 | L18: =(1-Parametros!$B$5)*B18 | M18: =-Parametros!$B$9*O17 | N18: =J18+K18+L18+M18 | O18: =IF(N18>=Parametros!$B$10,1,0) | Q18: =Parametros!$B$11*H18+(1-Parametros!$B$11)*O18
A19: 14 | B19: =Datos!$B$17 | C19: =Parametros!$B$4*G18 | D19: =Parametros!$B$6*N18 | E19: =(1-Parametros!$B$4)*B19 | F19: =-Parametros!$B$8*H18 | G19: =C19+D19+E19+F19 | H19: =IF(G19>=Parametros!$B$10,1,0) | J19: =Parametros!$B$5*N18 | K19: =Parametros!$B$7*G19 | L19: =(1-Parametros!$B$5)*B19 | M19: =-Parametros!$B$9*O18 | N19: =J19+K19+L19+M19 | O19: =IF(N19>=Parametros!$B$10,1,0) | Q19: =Parametros!$B$11*H19+(1-Parametros!$B$11)*O19
A20: 15 | B20: =Datos!$B$18 | C20: =Parametros!$B$4*G19 | D20: =Parametros!$B$6*N19 | E20: =(1-Parametros!$B$4)*B20 | F20: =-Parametros!$B$8*H19 | G20: =C20+D20+E20+F20 | H20: =IF(G20>=Parametros!$B$10,1,0) | J20: =Parametros!$B$5*N19 | K20: =Parametros!$B$7*G20 | L20: =(1-Parametros!$B$5)*B20 | M20: =-Parametros!$B$9*O19 | N20: =J20+K20+L20+M20 | O20: =IF(N20>=Parametros!$B$10,1,0) | Q20: =Parametros!$B$11*H20+(1-Parametros!$B$11)*O20
A21: 16 | B21: =Datos!$B$19 | C21: =Parametros!$B$4*G20 | D21: =Parametros!$B$6*N20 | E21: =(1-Parametros!$B$4)*B21 | F21: =-Parametros!$B$8*H20 | G21: =C21+D21+E21+F21 | H21: =IF(G21>=Parametros!$B$10,1,0) | J21: =Parametros!$B$5*N20 | K21: =Parametros!$B$7*G21 | L21: =(1-Parametros!$B$5)*B21 | M21: =-Parametros!$B$9*O20 | N21: =J21+K21+L21+M21 | O21: =IF(N21>=Parametros!$B$10,1,0) | Q21: =Parametros!$B$11*H21+(1-Parametros!$B$11)*O21
A22: 17 | B22: =Datos!$B$20 | C22: =Parametros!$B$4*G21 | D22: =Parametros!$B$6*N21 | E22: =(1-Parametros!$B$4)*B22 | F22: =-Parametros!$B$8*H21 | G22: =C22+D22+E22+F22 | H22: =IF(G22>=Parametros!$B$10,1,0) | J22: =Parametros!$B$5*N21 | K22: =Parametros!$B$7*G22 | L22: =(1-Parametros!$B$5)*B22 | M22: =-Parametros!$B$9*O21 | N22: =J22+K22+L22+M22 | O22: =IF(N22>=Parametros!$B$10,1,0) | Q22: =Parametros!$B$11*H22+(1-Parametros!$B$11)*O22
A23: 18 | B23: =Datos!$B$21 | C23: =Parametros!$B$4*G22 | D23: =Parametros!$B$6*N22 | E23: =(1-Parametros!$B$4)*B23 | F23: =-Parametros!$B$8*H22 | G23: =C23+D23+E23+F23 | H23: =IF(G23>=Parametros!$B$10,1,0) | J23: =Parametros!$B$5*N22 | K23: =Parametros!$B$7*G23 | L23: =(1-Parametros!$B$5)*B23 | M23: =-Parametros!$B$9*O22 | N23: =J23+K23+L23+M23 | O23: =IF(N23>=Parametros!$B$10,1,0) | Q23: =Parametros!$B$11*H23+(1-Parametros!$B$11)*O23
A24: 19 | B24: =Datos!$B$22 | C24: =Parametros!$B$4*G23 | D24: =Parametros!$B$6*N23 | E24: =(1-Parametros!$B$4)*B24 | F24: =-Parametros!$B$8*H23 | G24: =C24+D24+E24+F24 | H24: =IF(G24>=Parametros!$B$10,1,0) | J24: =Parametros!$B$5*N23 | K24: =Parametros!$B$7*G24 | L24: =(1-Parametros!$B$5)*B24 | M24: =-Parametros!$B$9*O23 | N24: =J24+K24+L24+M24 | O24: =IF(N24>=Parametros!$B$10,1,0) | Q24: =Parametros!$B$11*H24+(1-Parametros!$B$11)*O24
A25: 20 | B25: =Datos!$B$23 | C25: =Parametros!$B$4*G24 | D25: =Parametros!$B$6*N24 | E25: =(1-Parametros!$B$4)*B25 | F25: =-Parametros!$B$8*H24 | G25: =C25+D25+E25+F25 | H25: =IF(G25>=Parametros!$B$10,1,0) | J25: =Parametros!$B$5*N24 | K25: =Parametros!$B$7*G25 | L25: =(1-Parametros!$B$5)*B25 | M25: =-Parametros!$B$9*O24 | N25: =J25+K25+L25+M25 | O25: =IF(N25>=Parametros!$B$10,1,0) | Q25: =Parametros!$B$11*H25+(1-Parametros!$B$11)*O25
A26: 21 | B26: =Datos!$B$24 | C26: =Parametros!$B$4*G25 | D26: =Parametros!$B$6*N25 | E26: =(1-Parametros!$B$4)*B26 | F26: =-Parametros!$B$8*H25 | G26: =C26+D26+E26+F26 | H26: =IF(G26>=Parametros!$B$10,1,0) | J26: =Parametros!$B$5*N25 | K26: =Parametros!$B$7*G26 | L26: =(1-Parametros!$B$5)*B26 | M26: =-Parametros!$B$9*O25 | N26: =J26+K26+L26+M26 | O26: =IF(N26>=Parametros!$B$10,1,0) | Q26: =Parametros!$B$11*H26+(1-Parametros!$B$11)*O26
A27: 22 | B27: =Datos!$B$25 | C27: =Parametros!$B$4*G26 | D27: =Parametros!$B$6*N26 | E27: =(1-Parametros!$B$4)*B27 | F27: =-Parametros!$B$8*H26 | G27: =C27+D27+E27+F27 | H27: =IF(G27>=Parametros!$B$10,1,0) | J27: =Parametros!$B$5*N26 | K27: =Parametros!$B$7*G27 | L27: =(1-Parametros!$B$5)*B27 | M27: =-Parametros!$B$9*O26 | N27: =J27+K27+L27+M27 | O27: =IF(N27>=Parametros!$B$10,1,0) | Q27: =Parametros!$B$11*H27+(1-Parametros!$B$11)*O27
A28: 23 | B28: =Datos!$B$26 | C28: =Parametros!$B$4*G27 | D28: =Parametros!$B$6*N27 | E28: =(1-Parametros!$B$4)*B28 | F28: =-Parametros!$B$8*H27 | G28: =C28+D28+E28+F28 | H28: =IF(G28>=Parametros!$B$10,1,0) | J28: =Parametros!$B$5*N27 | K28: =Parametros!$B$7*G28 | L28: =(1-Parametros!$B$5)*B28 | M28: =-Parametros!$B$9*O27 | N28: =J28+K28+L28+M28 | O28: =IF(N28>=Parametros!$B$10,1,0) | Q28: =Parametros!$B$11*H28+(1-Parametros!$B$11)*O28
A29: 24 | B29: =Datos!$B$27 | C29: =Parametros!$B$4*G28 | D29: =Parametros!$B$6*N28 | E29: =(1-Parametros!$B$4)*B29 | F29: =-Parametros!$B$8*H28 | G29: =C29+D29+E29+F29 | H29: =IF(G29>=Parametros!$B$10,1,0) | J29: =Parametros!$B$5*N28 | K29: =Parametros!$B$7*G29 | L29: =(1-Parametros!$B$5)*B29 | M29: =-Parametros!$B$9*O28 | N29: =J29+K29+L29+M29 | O29: =IF(N29>=Parametros!$B$10,1,0) | Q29: =Parametros!$B$11*H29+(1-Parametros!$B$11)*O29
A30: 25 | B30: =Datos!$B$28 | C30: =Parametros!$B$4*G29 | D30: =Parametros!$B$6*N29 | E30: =(1-Parametros!$B$4)*B30 | F30: =-Parametros!$B$8*H29 | G30: =C30+D30+E30+F30 | H30: =IF(G30>=Parametros!$B$10,1,0) | J30: =Parametros!$B$5*N29 | K30: =Parametros!$B$7*G30 | L30: =(1-Parametros!$B$5)*B30 | M30: =-Parametros!$B$9*O29 | N30: =J30+K30+L30+M30 | O30: =IF(N30>=Parametros!$B$10,1,0) | Q30: =Parametros!$B$11*H30+(1-Parametros!$B$11)*O30
A31: 26 | B31: =Datos!$B$29 | C31: =Parametros!$B$4*G30 | D31: =Parametros!$B$6*N30 | E31: =(1-Parametros!$B$4)*B31 | F31: =-Parametros!$B$8*H30 | G31: =C31+D31+E31+F31 | H31: =IF(G31>=Parametros!$B$10,1,0) | J31: =Parametros!$B$5*N30 | K31: =Parametros!$B$7*G31 | L31: =(1-Parametros!$B$5)*B31 | M31: =-Parametros!$B$9*O30 | N31: =J31+K31+L31+M31 | O31: =IF(N31>=Parametros!$B$10,1,0) | Q31: =Parametros!$B$11*H31+(1-Parametros!$B$11)*O31
A32: 27 | B32: =Datos!$B$30 | C32: =Parametros!$B$4*G31 | D32: =Parametros!$B$6*N31 | E32: =(1-Parametros!$B$4)*B32 | F32: =-Parametros!$B$8*H31 | G32: =C32+D32+E32+F32 | H32: =IF(G32>=Parametros!$B$10,1,0) | J32: =Parametros!$B$5*N31 | K32: =Parametros!$B$7*G32 | L32: =(1-Parametros!$B$5)*B32 | M32: =-Parametros!$B$9*O31 | N32: =J32+K32+L32+M32 | O32: =IF(N32>=Parametros!$B$10,1,0) | Q32: =Parametros!$B$11*H32+(1-Parametros!$B$11)*O32
A33: 28 | B33: =Datos!$B$31 | C33: =Parametros!$B$4*G32 | D33: =Parametros!$B$6*N32 | E33: =(1-Parametros!$B$4)*B33 | F33: =-Parametros!$B$8*H32 | G33: =C33+D33+E33+F33 | H33: =IF(G33>=Parametros!$B$10,1,0) | J33: =Parametros!$B$5*N32 | K33: =Parametros!$B$7*G33 | L33: =(1-Parametros!$B$5)*B33 | M33: =-Parametros!$B$9*O32 | N33: =J33+K33+L33+M33 | O33: =IF(N33>=Parametros!$B$10,1,0) | Q33: =Parametros!$B$11*H33+(1-Parametros!$B$11)*O33
A34: 29 | B34: =Datos!$B$32 | C34: =Parametros!$B$4*G33 | D34: =Parametros!$B$6*N33 | E34: =(1-Parametros!$B$4)*B34 | F34: =-Parametros!$B$8*H33 | G34: =C34+D34+E34+F34 | H34: =IF(G34>=Parametros!$B$10,1,0) | J34: =Parametros!$B$5*N33 | K34: =Parametros!$B$7*G34 | L34: =(1-Parametros!$B$5)*B34 | M34: =-Parametros!$B$9*O33 | N34: =J34+K34+L34+M34 | O34: =IF(N34>=Parametros!$B$10,1,0) | Q34: =Parametros!$B$11*H34+(1-Parametros!$B$11)*O34
A35: 30 | B35: =Datos!$B$33 | C35: =Parametros!$B$4*G34 | D35: =Parametros!$B$6*N34 | E35: =(1-Parametros!$B$4)*B35 | F35: =-Parametros!$B$8*H34 | G35: =C35+D35+E35+F35 | H35: =IF(G35>=Parametros!$B$10,1,0) | J35: =Parametros!$B$5*N34 | K35: =Parametros!$B$7*G35 | L35: =(1-Parametros!$B$5)*B35 | M35: =-Parametros!$B$9*O34 | N35: =J35+K35+L35+M35 | O35: =IF(N35>=Parametros!$B$10,1,0) | Q35: =Parametros!$B$11*H35+(1-Parametros!$B$11)*O35
A36: 31 | B36: =Datos!$B$34 | C36: =Parametros!$B$4*G35 | D36: =Parametros!$B$6*N35 | E36: =(1-Parametros!$B$4)*B36 | F36: =-Parametros!$B$8*H35 | G36: =C36+D36+E36+F36 | H36: =IF(G36>=Parametros!$B$10,1,0) | J36: =Parametros!$B$5*N35 | K36: =Parametros!$B$7*G36 | L36: =(1-Parametros!$B$5)*B36 | M36: =-Parametros!$B$9*O35 | N36: =J36+K36+L36+M36 | O36: =IF(N36>=Parametros!$B$10,1,0) | Q36: =Parametros!$B$11*H36+(1-Parametros!$B$11)*O36
A37: 32 | B37: =Datos!$B$35 | C37: =Parametros!$B$4*G36 | D37: =Parametros!$B$6*N36 | E37: =(1-Parametros!$B$4)*B37 | F37: =-Parametros!$B$8*H36 | G37: =C37+D37+E37+F37 | H37: =IF(G37>=Parametros!$B$10,1,0) | J37: =Parametros!$B$5*N36 | K37: =Parametros!$B$7*G37 | L37: =(1-Parametros!$B$5)*B37 | M37: =-Parametros!$B$9*O36 | N37: =J37+K37+L37+M37 | O37: =IF(N37>=Parametros!$B$10,1,0) | Q37: =Parametros!$B$11*H37+(1-Parametros!$B$11)*O37
A38: 33 | B38: =Datos!$B$36 | C38: =Parametros!$B$4*G37 | D38: =Parametros!$B$6*N37 | E38: =(1-Parametros!$B$4)*B38 | F38: =-Parametros!$B$8*H37 | G38: =C38+D38+E38+F38 | H38: =IF(G38>=Parametros!$B$10,1,0) | J38: =Parametros!$B$5*N37 | K38: =Parametros!$B$7*G38 | L38: =(1-Parametros!$B$5)*B38 | M38: =-Parametros!$B$9*O37 | N38: =J38+K38+L38+M38 | O38: =IF(N38>=Parametros!$B$10,1,0) | Q38: =Parametros!$B$11*H38+(1-Parametros!$B$11)*O38
A39: 34 | B39: =Datos!$B$37 | C39: =Parametros!$B$4*G38 | D39: =Parametros!$B$6*N38 | E39: =(1-Parametros!$B$4)*B39 | F39: =-Parametros!$B$8*H38 | G39: =C39+D39+E39+F39 | H39: =IF(G39>=Parametros!$B$10,1,0) | J39: =Parametros!$B$5*N38 | K39: =Parametros!$B$7*G39 | L39: =(1-Parametros!$B$5)*B39 | M39: =-Parametros!$B$9*O38 | N39: =J39+K39+L39+M39 | O39: =IF(N39>=Parametros!$B$10,1,0) | Q39: =Parametros!$B$11*H39+(1-Parametros!$B$11)*O39
A40: 35 | B40: =Datos!$B$38 | C40: =Parametros!$B$4*G39 | D40: =Parametros!$B$6*N39 | E40: =(1-Parametros!$B$4)*B40 | F40: =-Parametros!$B$8*H39 | G40: =C40+D40+E40+F40 | H40: =IF(G40>=Parametros!$B$10,1,0) | J40: =Parametros!$B$5*N39 | K40: =Parametros!$B$7*G40 | L40: =(1-Parametros!$B$5)*B40 | M40: =-Parametros!$B$9*O39 | N40: =J40+K40+L40+M40 | O40: =IF(N40>=Parametros!$B$10,1,0) | Q40: =Parametros!$B$11*H40+(1-Parametros!$B$11)*O40
...

Sheet Grafico
A1: t | B1: c[t] entrada | C1: vd[t] dendrita | D1: vs[t] soma
A2: 0 | B2: =Simulacion!B5 | C2: =Simulacion!G5 | D2: =Simulacion!N5
A3: 1 | B3: =Simulacion!B6 | C3: =Simulacion!G6 | D3: =Simulacion!N6
A4: 2 | B4: =Simulacion!B7 | C4: =Simulacion!G7 | D4: =Simulacion!N7
A5: 3 | B5: =Simulacion!B8 | C5: =Simulacion!G8 | D5: =Simulacion!N8
A6: 4 | B6: =Simulacion!B9 | C6: =Simulacion!G9 | D6: =Simulacion!N9
A7: 5 | B7: =Simulacion!B10 | C7: =Simulacion!G10 | D7: =Simulacion!N10
A8: 6 | B8: =Simulacion!B11 | C8: =Simulacion!G11 | D8: =Simulacion!N11
A9: 7 | B9: =Simulacion!B12 | C9: =Simulacion!G12 | D9: =Simulacion!N12
A10: 8 | B10: =Simulacion!B13 | C10: =Simulacion!G13 | D10: =Simulacion!N13
A11: 9 | B11: =Simulacion!B14 | C11: =Simulacion!G14 | D11: =Simulacion!N14
A12: 10 | B12: =Simulacion!B15 | C12: =Simulacion!G15 | D12: =Simulacion!N15
A13: 11 | B13: =Simulacion!B16 | C13: =Simulacion!G16 | D13: =Simulacion!N16
... A169: 167 | B169: =Simulacion!B172 | C169: =Simulacion!G172 | D169: =Simulacion!N172
