Workbook

Sheet Resumen
A1: APRENDIZAJE SUPERVISADO — SEGUIMIENTO DE ESTUDIO | J1: TODOS LOS TEMAS DEL CURSO — 34 temas (nivel 0 y 1, los 5 bloques)
J2: Código | K2: Bloque | L2: Tema | M2: Estado | N2: Prioridad
A3: Este libro conserva tus estados de estudio (columna E de «Mapa de estudio»: no se modificaron). La columna F da la explicación sencilla y las columnas K a O reúnen el conocimiento del curso: definición precisa y fórmula, ejemplo o código, errores comunes, una pregunta de comprobación y la fuente exacta. El mismo contenido, con escenas y profundización, está en la carpeta «2_Prompt_para_video» (archivo único PROMPT_VIDEO_APRENDIZAJE_SUPERVISADO.md) para que otra IA te lo explique en video. Comprendido aún no significa firme. | J3: ='Mapa de estudio'!A2 | K3: =J3 | L3: ='Mapa de estudio'!C2 | M3: ='Mapa de estudio'!E2 | N3: ='Mapa de estudio'!H2
J4: ='Mapa de estudio'!A3 | K4: =J4 | L4: ='Mapa de estudio'!C3 | M4: ='Mapa de estudio'!E3 | N4: ='Mapa de estudio'!H3
A5: Total conceptos | C5: Firmes | E5: Pendientes | G5: Débiles | J5: ='Mapa de estudio'!A11 | K5: =J5 | L5: ='Mapa de estudio'!C11 | M5: ='Mapa de estudio'!E11 | N5: ='Mapa de estudio'!H11
A6: =COUNTA('Mapa de estudio'!$A$2:$A$186) | C6: =COUNTIF('Mapa de estudio'!$E$2:$E$186,"🟢 Firme") | E6: =COUNTIF('Mapa de estudio'!$E$2:$E$186,"⚪ Pendiente") | G6: =COUNTIF('Mapa de estudio'!$E$2:$E$186,"🔴 Débil") | J6: ='Mapa de estudio'!A18 | K6: =J6 | L6: ='Mapa de estudio'!C18 | M6: ='Mapa de estudio'!E18 | N6: ='Mapa de estudio'!H18
J7: ='Mapa de estudio'!A25 | K7: =J7 | L7: ='Mapa de estudio'!C25 | M7: ='Mapa de estudio'!E25 | N7: ='Mapa de estudio'!H25
J8: ='Mapa de estudio'!A28 | K8: =J8 | L8: ='Mapa de estudio'!C28 | M8: ='Mapa de estudio'!E28 | N8: ='Mapa de estudio'!H28
A9: Estado | B9: Cantidad | D9: TEMA EN CURSO — TEMA 1: FUNDAMENTOS Y PREPARACIÓN DE DATOS (ver los 5 temas completos en J:N) | J9: ='Mapa de estudio'!A33 | K9: =J9 | L9: ='Mapa de estudio'!C33 | M9: ='Mapa de estudio'!E33 | N9: ='Mapa de estudio'!H33
A10: 🟢 Firme | B10: =COUNTIF('Mapa de estudio'!$E$2:$E$186,A10) | D10: Concepto | E10: Estado | F10: Idea clave | G10: Siguiente | H10: Prioridad | J10: ='Mapa de estudio'!A39 | K10: =J10 | L10: ='Mapa de estudio'!C39 | M10: ='Mapa de estudio'!E39 | N10: ='Mapa de estudio'!H39
A11: 🟢 Comprendido | B11: =COUNTIF('Mapa de estudio'!$E$2:$E$186,A11) | D11: ='Mapa de estudio'!C3 | E11: ='Mapa de estudio'!E3 | F11: ='Mapa de estudio'!F3&"" | G11: ='Mapa de estudio'!G3&"" | H11: ='Mapa de estudio'!H3 | J11: ='Mapa de estudio'!A44 | K11: =J11 | L11: ='Mapa de estudio'!C44 | M11: ='Mapa de estudio'!E44 | N11: ='Mapa de estudio'!H44
A12: 🟡 Repasar | B12: =COUNTIF('Mapa de estudio'!$E$2:$E$186,A12) | D12: ='Mapa de estudio'!C11 | E12: ='Mapa de estudio'!E11 | F12: ='Mapa de estudio'!F11&"" | G12: ='Mapa de estudio'!G11&"" | H12: ='Mapa de estudio'!H11 | J12: ='Mapa de estudio'!A50 | K12: =J12 | L12: ='Mapa de estudio'!C50 | M12: ='Mapa de estudio'!E50 | N12: ='Mapa de estudio'!H50
A13: 🟠 Iniciado | B13: =COUNTIF('Mapa de estudio'!$E$2:$E$186,A13) | D13: ='Mapa de estudio'!C18 | E13: ='Mapa de estudio'!E18 | F13: ='Mapa de estudio'!F18&"" | G13: ='Mapa de estudio'!G18&"" | H13: ='Mapa de estudio'!H18 | J13: ='Mapa de estudio'!A51 | K13: =J13 | L13: ='Mapa de estudio'!C51 | M13: ='Mapa de estudio'!E51 | N13: ='Mapa de estudio'!H51
A14: 🟠 Parcial | B14: =COUNTIF('Mapa de estudio'!$E$2:$E$186,A14) | D14: ='Mapa de estudio'!C25 | E14: ='Mapa de estudio'!E25 | F14: ='Mapa de estudio'!F25&"" | G14: ='Mapa de estudio'!G25&"" | H14: ='Mapa de estudio'!H25 | J14: ='Mapa de estudio'!A57 | K14: =J14 | L14: ='Mapa de estudio'!C57 | M14: ='Mapa de estudio'!E57 | N14: ='Mapa de estudio'!H57
A15: ⚪ Pendiente | B15: =COUNTIF('Mapa de estudio'!$E$2:$E$186,A15) | D15: ='Mapa de estudio'!C28 | E15: ='Mapa de estudio'!E28 | F15: ='Mapa de estudio'!F28&"" | G15: ='Mapa de estudio'!G28&"" | H15: ='Mapa de estudio'!H28 | J15: ='Mapa de estudio'!A62 | K15: =J15 | L15: ='Mapa de estudio'!C62 | M15: ='Mapa de estudio'!E62 | N15: ='Mapa de estudio'!H62
A16: 🔴 Débil | B16: =COUNTIF('Mapa de estudio'!$E$2:$E$186,A16) | D16: ='Mapa de estudio'!C33 | E16: ='Mapa de estudio'!E33 | F16: ='Mapa de estudio'!F33&"" | G16: ='Mapa de estudio'!G33&"" | H16: ='Mapa de estudio'!H33 | J16: ='Mapa de estudio'!A68 | K16: =J16 | L16: ='Mapa de estudio'!C68 | M16: ='Mapa de estudio'!E68 | N16: ='Mapa de estudio'!H68
D17: ='Mapa de estudio'!C39 | E17: ='Mapa de estudio'!E39 | F17: ='Mapa de estudio'!F39&"" | G17: ='Mapa de estudio'!G39&"" | H17: ='Mapa de estudio'!H39 | J17: ='Mapa de estudio'!A73 | K17: =J17 | L17: ='Mapa de estudio'!C73 | M17: ='Mapa de estudio'!E73 | N17: ='Mapa de estudio'!H73
D18: ='Mapa de estudio'!C44 | E18: ='Mapa de estudio'!E44 | F18: ='Mapa de estudio'!F44&"" | G18: ='Mapa de estudio'!G44&"" | H18: ='Mapa de estudio'!H44 | J18: ='Mapa de estudio'!A79 | K18: =J18 | L18: ='Mapa de estudio'!C79 | M18: ='Mapa de estudio'!E79 | N18: ='Mapa de estudio'!H79
J19: ='Mapa de estudio'!A87 | K19: =J19 | L19: ='Mapa de estudio'!C87 | M19: ='Mapa de estudio'!E87 | N19: ='Mapa de estudio'!H87
A20: Criterio de avance: «Firme» exige resolver un caso nuevo. «Comprendido» significa que puedes explicarlo, pero todavía falta comprobar su aplicación. Los contadores y porcentajes de firmeza usan solo el estado «Firme». | J20: ='Mapa de estudio'!A88 | K20: =J20 | L20: ='Mapa de estudio'!C88 | M20: ='Mapa de estudio'!E88 | N20: ='Mapa de estudio'!H88
J21: ='Mapa de estudio'!A93 | K21: =J21 | L21: ='Mapa de estudio'!C93 | M21: ='Mapa de estudio'!E93 | N21: ='Mapa de estudio'!H93
A22: PROGRESO POR BLOQUE — LOS 5 TEMAS DEL CURSO | J22: ='Mapa de estudio'!A96 | K22: =J22 | L22: ='Mapa de estudio'!C96 | M22: ='Mapa de estudio'!E96 | N22: ='Mapa de estudio'!H96
A23: Bloque | B23: Total | C23: 🟢 Firme | D23: 🟠 En progreso | E23: 🟡 Repasar | F23: ⚪ Pendiente | G23: 🔴 Débil | H23: % Firme | J23: ='Mapa de estudio'!A101 | K23: =J23 | L23: ='Mapa de estudio'!C101 | M23: ='Mapa de estudio'!E101 | N23: ='Mapa de estudio'!H101
A24: 1. Fundamentos y preparación de datos | B24: =COUNTIF('Mapa de estudio'!$B$2:$B$186,$A24) | C24: =COUNTIFS('Mapa de estudio'!$B$2:$B$186,$A24,'Mapa de estudio'!$E$2:$E$186,"🟢 Firme") | D24: =COUNTIFS('Mapa de estudio'!$B$2:$B$186,$A24,'Mapa de estudio'!$E$2:$E$186,"🟢 Comprendido")+COUNTIFS('Mapa de estudio'!$B$2:$B$186,$A24,'Mapa de estudio'!$E$2:$E$186,"🟠 Iniciado")+COUNTIFS('Mapa de estudio'!$B$2:$B$186,$A24,'Mapa de estudio'!$E$2:$E$186,"🟠 Parcial") | E24: =COUNTIFS('Mapa de estudio'!$B$2:$B$186,$A24,'Mapa de estudio'!$E$2:$E$186,"🟡 Repasar") | F24: =COUNTIFS('Mapa de estudio'!$B$2:$B$186,$A24,'Mapa de estudio'!$E$2:$E$186,"⚪ Pendiente") | G24: =COUNTIFS('Mapa de estudio'!$B$2:$B$186,$A24,'Mapa de estudio'!$E$2:$E$186,"🔴 Débil") | H24: =IF(B24=0,0,C24/B24) | J24: ='Mapa de estudio'!A102 | K24: =J24 | L24: ='Mapa de estudio'!C102 | M24: ='Mapa de estudio'!E102 | N24: ='Mapa de estudio'!H102
A25: 2. Validación de modelos y métricas | B25: =COUNTIF('Mapa de estudio'!$B$2:$B$186,$A25) | C25: =COUNTIFS('Mapa de estudio'!$B$2:$B$186,$A25,'Mapa de estudio'!$E$2:$E$186,"🟢 Firme") | D25: =COUNTIFS('Mapa de estudio'!$B$2:$B$186,$A25,'Mapa de estudio'!$E$2:$E$186,"🟢 Comprendido")+COUNTIFS('Mapa de estudio'!$B$2:$B$186,$A25,'Mapa de estudio'!$E$2:$E$186,"🟠 Iniciado")+COUNTIFS('Mapa de estudio'!$B$2:$B$186,$A25,'Mapa de estudio'!$E$2:$E$186,"🟠 Parcial") | E25: =COUNTIFS('Mapa de estudio'!$B$2:$B$186,$A25,'Mapa de estudio'!$E$2:$E$186,"🟡 Repasar") | F25: =COUNTIFS('Mapa de estudio'!$B$2:$B$186,$A25,'Mapa de estudio'!$E$2:$E$186,"⚪ Pendiente") | G25: =COUNTIFS('Mapa de estudio'!$B$2:$B$186,$A25,'Mapa de estudio'!$E$2:$E$186,"🔴 Débil") | H25: =IF(B25=0,0,C25/B25) | J25: ='Mapa de estudio'!A106 | K25: =J25 | L25: ='Mapa de estudio'!C106 | M25: ='Mapa de estudio'!E106 | N25: ='Mapa de estudio'!H106
A26: 3. Extracción de características | B26: =COUNTIF('Mapa de estudio'!$B$2:$B$186,$A26) | C26: =COUNTIFS('Mapa de estudio'!$B$2:$B$186,$A26,'Mapa de estudio'!$E$2:$E$186,"🟢 Firme") | D26: =COUNTIFS('Mapa de estudio'!$B$2:$B$186,$A26,'Mapa de estudio'!$E$2:$E$186,"🟢 Comprendido")+COUNTIFS('Mapa de estudio'!$B$2:$B$186,$A26,'Mapa de estudio'!$E$2:$E$186,"🟠 Iniciado")+COUNTIFS('Mapa de estudio'!$B$2:$B$186,$A26,'Mapa de estudio'!$E$2:$E$186,"🟠 Parcial") | E26: =COUNTIFS('Mapa de estudio'!$B$2:$B$186,$A26,'Mapa de estudio'!$E$2:$E$186,"🟡 Repasar") | F26: =COUNTIFS('Mapa de estudio'!$B$2:$B$186,$A26,'Mapa de estudio'!$E$2:$E$186,"⚪ Pendiente") | G26: =COUNTIFS('Mapa de estudio'!$B$2:$B$186,$A26,'Mapa de estudio'!$E$2:$E$186,"🔴 Débil") | H26: =IF(B26=0,0,C26/B26) | J26: ='Mapa de estudio'!A111 | K26: =J26 | L26: ='Mapa de estudio'!C111 | M26: ='Mapa de estudio'!E111 | N26: ='Mapa de estudio'!H111
A27: 4. Modelos de regresión | B27: =COUNTIF('Mapa de estudio'!$B$2:$B$186,$A27) | C27: =COUNTIFS('Mapa de estudio'!$B$2:$B$186,$A27,'Mapa de estudio'!$E$2:$E$186,"🟢 Firme") | D27: =COUNTIFS('Mapa de estudio'!$B$2:$B$186,$A27,'Mapa de estudio'!$E$2:$E$186,"🟢 Comprendido")+COUNTIFS('Mapa de estudio'!$B$2:$B$186,$A27,'Mapa de estudio'!$E$2:$E$186,"🟠 Iniciado")+COUNTIFS('Mapa de estudio'!$B$2:$B$186,$A27,'Mapa de estudio'!$E$2:$E$186,"🟠 Parcial") | E27: =COUNTIFS('Mapa de estudio'!$B$2:$B$186,$A27,'Mapa de estudio'!$E$2:$E$186,"🟡 Repasar") | F27: =COUNTIFS('Mapa de estudio'!$B$2:$B$186,$A27,'Mapa de estudio'!$E$2:$E$186,"⚪ Pendiente") | G27: =COUNTIFS('Mapa de estudio'!$B$2:$B$186,$A27,'Mapa de estudio'!$E$2:$E$186,"🔴 Débil") | H27: =IF(B27=0,0,C27/B27) | J27: ='Mapa de estudio'!A116 | K27: =J27 | L27: ='Mapa de estudio'!C116 | M27: ='Mapa de estudio'!E116 | N27: ='Mapa de estudio'!H116
A28: 5. Modelos de clasificación | B28: =COUNTIF('Mapa de estudio'!$B$2:$B$186,$A28) | C28: =COUNTIFS('Mapa de estudio'!$B$2:$B$186,$A28,'Mapa de estudio'!$E$2:$E$186,"🟢 Firme") | D28: =COUNTIFS('Mapa de estudio'!$B$2:$B$186,$A28,'Mapa de estudio'!$E$2:$E$186,"🟢 Comprendido")+COUNTIFS('Mapa de estudio'!$B$2:$B$186,$A28,'Mapa de estudio'!$E$2:$E$186,"🟠 Iniciado")+COUNTIFS('Mapa de estudio'!$B$2:$B$186,$A28,'Mapa de estudio'!$E$2:$E$186,"🟠 Parcial") | E28: =COUNTIFS('Mapa de estudio'!$B$2:$B$186,$A28,'Mapa de estudio'!$E$2:$E$186,"🟡 Repasar") | F28: =COUNTIFS('Mapa de estudio'!$B$2:$B$186,$A28,'Mapa de estudio'!$E$2:$E$186,"⚪ Pendiente") | G28: =COUNTIFS('Mapa de estudio'!$B$2:$B$186,$A28,'Mapa de estudio'!$E$2:$E$186,"🔴 Débil") | H28: =IF(B28=0,0,C28/B28) | J28: ='Mapa de estudio'!A120 | K28: =J28 | L28: ='Mapa de estudio'!C120 | M28: ='Mapa de estudio'!E120 | N28: ='Mapa de estudio'!H120
A29: TOTAL CURSO | B29: =SUM(B24:B28) | C29: =SUM(C24:C28) | D29: =SUM(D24:D28) | E29: =SUM(E24:E28) | F29: =SUM(F24:F28) | G29: =SUM(G24:G28) | H29: =IF(B29=0,0,C29/B29) | J29: ='Mapa de estudio'!A126 | K29: =J29 | L29: ='Mapa de estudio'!C126 | M29: ='Mapa de estudio'!E126 | N29: ='Mapa de estudio'!H126
A30: Orden pedagógico del curso: Bloque 1 → 2 → 3 → 4 → 5 (respeta el orden real de las carpetas tema1-tema5 del repositorio). El bloque 3 (Extracción de características) va antes de los modelos de regresión/clasificación porque construye las variables/features que luego usan los temas 4 y 5. Ninguno está iniciado todavía. | J30: ='Mapa de estudio'!A127 | K30: =J30 | L30: ='Mapa de estudio'!C127 | M30: ='Mapa de estudio'!E127 | N30: ='Mapa de estudio'!H127
J31: ='Mapa de estudio'!A138 | K31: =J31 | L31: ='Mapa de estudio'!C138 | M31: ='Mapa de estudio'!E138 | N31: ='Mapa de estudio'!H138
J32: ='Mapa de estudio'!A142 | K32: =J32 | L32: ='Mapa de estudio'!C142 | M32: ='Mapa de estudio'!E142 | N32: ='Mapa de estudio'!H142
J33: ='Mapa de estudio'!A153 | K33: =J33 | L33: ='Mapa de estudio'!C153 | M33: ='Mapa de estudio'!E153 | N33: ='Mapa de estudio'!H153
J34: ='Mapa de estudio'!A154 | K34: =J34 | L34: ='Mapa de estudio'!C154 | M34: ='Mapa de estudio'!E154 | N34: ='Mapa de estudio'!H154
J35: ='Mapa de estudio'!A168 | K35: =J35 | L35: ='Mapa de estudio'!C168 | M35: ='Mapa de estudio'!E168 | N35: ='Mapa de estudio'!H168
J36: ='Mapa de estudio'!A183 | K36: =J36 | L36: ='Mapa de estudio'!C183 | M36: ='Mapa de estudio'!E183 | N36: ='Mapa de estudio'!H183

Sheet Mapa de estudio
A1: Código | B1: Bloque | C1: Tema / concepto | D1: Nivel | E1: Estado | F1: Explicación sencilla | G1: Siguiente aplicación | H1: Prioridad | I1: Actualizado | J1: Fuente | K1: Definición precisa y fórmula | L1: Ejemplo o código | M1: Ojo: error común o límite | N1: Pregunta de comprobación (una sola) | O1: Fuente exacta (archivo, sección, página o diapositiva)
A2: 1 | B2: 1. Fundamentos y preparación de datos | C2: FUNDAMENTOS Y PREPARACIÓN DE DATOS | D2: 0 | E2: 🟢 Comprendido | F2: Es la base del curso: aprender a organizar un proyecto, distinguir tipos de aprendizaje, leer una tabla de datos y prepararla. Si entiendes estas piezas, puedes interpretar por qué un modelo funciona o falla. | G2: Repasar CRISP-DM y tipos de aprendizaje primero; luego las 4 técnicas de limpieza en orden (normalización, outliers, imputación, selección). | H2: Alta | I2: 27/09/2026 | J2: 02_tema1_fundamentos_y_preparacion_datos.txt | K2: Bloque 1: método de trabajo (CRISP-DM), tipos de aprendizaje, estructura de una tabla de datos (instancias, atributos, clase) y cuatro técnicas de preparación: normalizar o estandarizar, detectar outliers, imputar ausentes y seleccionar atributos. | L2: Ruta mínima de un proyecto: definir la pregunta, mirar los datos, limpiarlos, separar entrenamiento y test, entrenar, evaluar. | M2: Toda transformación que aprende algo de los datos (mínimo, media, mediana de relleno, atributos elegidos) se aprende solo con entrenamiento. | N2: ¿Por qué la preparación de datos es la fase donde un error pasa más desapercibido? | O2: Archivo 02 (manual PDF p.6-31 + 3 notebooks).
A3: 1.1 | B3: 1. Fundamentos y preparación de datos | C3: Metodología CRISP-DM | D3: 1 | E3: 🟢 Comprendido | F3: Es el método más usado para llevar un proyecto de aprendizaje automático de principio a fin. Tiene 6 fases que se siguen en orden, pero se puede volver atrás y repetir pasos. Sirve para no improvisar y mantener el trabajo ordenado. | G3: Aplicar las 6 fases a un caso real y ubicar en qué fase encaja cada tarea del curso (limpieza, modelado, evaluación). | H3: Alta | I3: 27/09/2026 | J3: 02_tema1_fundamentos_y_preparacion_datos.txt | K3: CRISP-DM (Cross-Industry Standard Process for Data Mining): concebido a fines de 1996, proyecto europeo de 1997 codirigido por SPSS, Teradata, NCR, Daimler AG y Ohra; primera versión en 1999. Seis fases con dependencias secuenciales y cíclicas. Alternativas: KDD (1996, sin comprensión del negocio ni despliegue), SEMMA y ASUM-DM (IBM, 2015). | L3: Fases: 1 comprensión del negocio, 2 comprensión de los datos, 3 preparación, 4 modelado, 5 evaluación de negocio, 6 despliegue; se puede volver atrás desde cualquiera. | M3: No es una secuencia rígida: un hallazgo en la evaluación puede obligar a redefinir el objetivo o a preparar de nuevo los datos. | N3: ¿Por qué la evaluación de negocio (fase 5) no es lo mismo que medir la exactitud del modelo? | O3: 02 §1; PDF p.7-8.
A4: 1.1.a | B4: 1. Fundamentos y preparación de datos | C4: Fase 1: Comprensión del negocio | D4: 2 | E4: 🟢 Comprendido | F4: Es el primer paso, y se retoma durante todo el proyecto: definir qué quiere lograr el negocio y cómo sabrán que salió bien, revisar la situación actual, traducir esas metas a tareas técnicas y armar un plan. Así se evita trabajar sin rumbo. | H4: Media | I4: 27/09/2026 | J4: 02_tema1_fundamentos_y_preparacion_datos.txt | K4: Tareas: determinar objetivos de negocio y criterios de éxito (cualitativos o cuantitativos), evaluar la situación actual, determinar los objetivos de minería de datos (traducir metas de negocio a metas técnicas) y producir un plan de proyecto. Debe retomarse durante todo el proyecto. | L4: Negocio: reducir la fuga de clientes. Meta técnica: predecir la baja del próximo mes con la información disponible al inicio de ese mes. | M4: Sin criterio de éxito fijado antes, cualquier resultado se puede presentar como bueno. | N4: ¿Qué diferencia hay entre un objetivo de negocio y un objetivo de minería de datos? | O4: 02 §1; PDF p.10-15 (detalle de las fases).
A5: 1.1.b | B5: 1. Fundamentos y preparación de datos | C5: Fase 2: Comprensión de los datos | D5: 2 | E5: 🟢 Comprendido | F5: Se reúnen los datos y se los revisa por primera vez: se describen, se resumen con números y gráficos de barras, y se busca si faltan datos o hay valores imposibles. Hacerlo bien ahorra tiempo en el resto del proyecto. | H5: Media | I5: 27/09/2026 | J5: 02_tema1_fundamentos_y_preparacion_datos.txt | K5: Tareas: recolectar datos iniciales, describirlos (filas, columnas, significado, formato), explorarlos (estadística descriptiva, tablas de frecuencia, histogramas) y verificar su calidad (nulos, valores fuera de rango, consistencia). Reduce el tiempo total y aumenta las garantías de éxito. | L5: Revisar con describe() y isna().sum() cuántos nulos y qué rangos tiene cada columna antes de modelar. | M5: Saltarse esta fase suele costar más tiempo después, cuando el modelo falla por datos mal entendidos. | N5: ¿Qué dos hallazgos de esta fase cambiarían tu plan de preparación? | O5: 02 §1; PDF p.10-15 (detalle de las fases).
A6: 1.1.c | B6: 1. Fundamentos y preparación de datos | C6: Fase 3: Preparación de los datos | D6: 2 | E6: 🟢 Comprendido | F6: Es la fase más crítica: se eligen, limpian y arreglan los datos para que el modelo (el programa que aprende) pueda usarlos. Si un error pasa sin detectarse aquí, llega al modelo y arruina sus resultados. | H6: Alta | I6: 27/09/2026 | J6: 02_tema1_fundamentos_y_preparacion_datos.txt | K6: Seleccionar, limpiar y generar los conjuntos preparados para modelar. Tareas: seleccionar datos; limpiar (selección de columnas, reducción de filas, normalización, discretización, outliers, imputación); construir datos (p. ej. superficie = largo x ancho); integrar (fusionar tablas); formatear sin cambiar el contenido. Es la fase más crítica y la que más tiempo consume. | L6: Crear la columna superficie = largo x ancho y rellenar las edades ausentes con la mediana de entrenamiento. | M6: Los errores no detectados aquí se trasladan al modelado y son difíciles de rastrear. | N6: ¿Por qué un error de preparación es más peligroso que un error del algoritmo? | O6: 02 §1; PDF p.10-15 (detalle de las fases).
A7: 1.1.d | B7: 1. Fundamentos y preparación de datos | C7: Fase 4: Modelado | D7: 2 | E7: 🟢 Comprendido | F7: Es la fase central de la asignatura: se eligen los algoritmos (métodos de cálculo), se define cómo probarlos y con qué medidas, se construyen los modelos y se revisa técnicamente qué tan bien funcionan. | H7: Alta | I7: 27/09/2026 | J7: 02_tema1_fundamentos_y_preparacion_datos.txt | K7: Crear modelos de conocimiento (clasificación, regresión, etc.) con los datos preparados. Subtareas: seleccionar algoritmos (criterios: tipo de aprendizaje, compatibilidad con los datos, complejidad, interpretabilidad: caja blanca frente a caja negra), generar el plan de prueba (parámetros, métricas, forma de validar), construir los modelos y evaluar técnicamente (ranking de algoritmos). | L7: Comparar regresión logística y un árbol con la misma validación cruzada y las mismas métricas. | M7: Un modelo más complejo no siempre es mejor: se compara con la misma validación y se considera la interpretabilidad. | N7: ¿Qué ventaja tiene un modelo de caja blanca frente a uno de caja negra? | O7: 02 §1; PDF p.10-15 (detalle de las fases).
A8: 1.1.e | B8: 1. Fundamentos y preparación de datos | C8: Fase 5: Evaluación de negocio | D8: 2 | E8: 🟢 Comprendido | F8: Se comprueba si los modelos cumplen lo que el negocio pidió al inicio como éxito. También se revisa cómo se trabajó y se decide si terminar, repetir pasos o iniciar nuevos proyectos. Así se confirma que el resultado sirve de verdad. | H8: Media | I8: 27/09/2026 | J8: 02_tema1_fundamentos_y_preparacion_datos.txt | K8: Evaluar los modelos frente a los criterios de éxito de negocio definidos al inicio. Tareas: evaluar resultados, revisar el proceso (aseguramiento de calidad) y determinar los siguientes pasos (finalizar, iterar o abrir nuevos subproyectos). | L8: Un modelo con buena exactitud puede no cumplir el criterio de negocio si no detecta los casos costosos. | M8: Es una evaluación contra el objetivo del negocio, no solo contra una métrica técnica. | N8: ¿Qué tres decisiones puede tomar el equipo al cerrar esta fase? | O8: 02 §1; PDF p.10-15 (detalle de las fases).
A9: 1.1.f | B9: 1. Fundamentos y preparación de datos | C9: Fase 6: Despliegue | D9: 2 | E9: 🟢 Comprendido | F9: Lo aprendido se convierte en acciones reales dentro del negocio: se planea cómo ponerlo en uso, se vigila y mantiene, se escribe un informe final y se revisa el proyecto. Sin este paso, el análisis queda sin utilidad práctica. | H9: Media | I9: 27/09/2026 | J9: 02_tema1_fundamentos_y_preparacion_datos.txt | K9: Transformar el conocimiento obtenido en acciones dentro del proceso de negocio. Tareas: planear la implementación, monitorizar y mantener (detectar comportamientos anómalos), crear el informe final y revisar el proyecto (lecciones aprendidas). | L9: Poner el modelo a puntuar cada noche y vigilar si su rendimiento cae con el tiempo. | M9: Un modelo desplegado se degrada si cambian los datos: requiere monitorización. | N9: ¿Por qué hay que seguir vigilando un modelo después de desplegarlo? | O9: 02 §1; PDF p.10-15 (detalle de las fases).
A10: 1.1.g | B10: 1. Fundamentos y preparación de datos | C10: Roles en ciencia de datos | D10: 2 | E10: 🟢 Comprendido | F10: Un equipo que trabaja con datos suele tener cuatro roles: director técnico (data scientist chief), científico de datos (data scientist), analista de datos (data analyst) e ingeniero de datos (data engineer). Cada uno cumple una función distinta dentro del proyecto. | H10: Baja | I10: 27/09/2026 | J10: 02_tema1_fundamentos_y_preparacion_datos.txt | K10: Cuatro roles típicos: director técnico (data scientist chief: planifica, asigna recursos, valida), científico de datos (data scientist: analiza, diseña, experimenta, interpreta), analista de datos (data analyst: inteligencia de negocio, informes, cuadros de mando) e ingeniero de datos (data engineer: extrae, limpia, transforma, carga y automatiza). También hay ingenieros de software, administradores de BD y diseñadores gráficos. | L10: El ingeniero de datos arma el flujo que carga las tablas; el científico de datos construye el modelo sobre ellas. | M10: Es un complemento del manual (apartado 1.1.3): no forma parte de CRISP-DM en sí. | N10: ¿Qué rol se encarga de automatizar la carga y transformación de los datos? | O10: 02 §1; PDF p.9.
A11: 1.2 | B11: 1. Fundamentos y preparación de datos | C11: Tipos de aprendizaje (supervisado / no supervisado / otros) | D11: 1 | E11: 🟢 Comprendido | F11: Hay dos grandes tipos de aprendizaje. Si los datos incluyen la respuesta que se quiere acertar, es supervisado: se usa para predecir. Si no la incluyen, es no supervisado. También existen variantes intermedias, como semisupervisado y por refuerzo. | G11: Practicar clasificando problemas reales como regresión, clasificación, clustering o reglas de asociación. | H11: Alta | I11: 27/09/2026 | J11: 02_tema1_fundamentos_y_preparacion_datos.txt | K11: Dos categorías: problemas con variable de salida (supervisado) y sin ella (no supervisado). Otros tipos: semisupervisado y por refuerzo. Además existen tareas de apoyo como la reducción de dimensionalidad, la discretización o la selección de instancias y atributos. | L11: Predecir el precio de una casa con ejemplos de precios conocidos es supervisado; agrupar clientes parecidos sin etiqueta es no supervisado. | M11: Que una columna esté escrita con números no la convierte en regresión: los códigos 0 y 1 pueden ser clases. | N11: ¿Qué dato necesitas para que un problema sea supervisado? | O11: 02 §2; PDF p.15-17.
A12: 1.2.a | B12: 1. Fundamentos y preparación de datos | C12: Aprendizaje supervisado: regresión vs. clasificación | D12: 2 | E12: 🟢 Comprendido | F12: Aquí se calcula una respuesta a partir de los demás datos. Si la respuesta es un número, se llama regresión; si es una categoría o etiqueta, clasificación. Todas las filas necesitan tener su respuesta, porque de ahí aprende el modelo. | H12: Alta | I12: 27/09/2026 | J12: 02_tema1_fundamentos_y_preparacion_datos.txt | K12: Se estima el valor de la variable de salida a partir del resto de variables. Regresión: salida numérica (número real). Clasificación: salida categórica (etiqueta o número discreto). Es imprescindible que todas las filas tengan valor de salida; sin él, esa fila no aporta aprendizaje. | L12: Precio de la vivienda: regresión. Especie de iris (setosa, versicolor, virginica): clasificación. | M12: Una columna numérica puede ser una clase (0 y 1); y una entrada categórica puede usarse en regresión tras codificarla. | N12: Si la salida es la talla S, M o L, ¿es regresión o clasificación y por qué? | O12: 02 §2; PDF p.15-16.
A13: 1.2.b | B13: 1. Fundamentos y preparación de datos | C13: Aprendizaje no supervisado: clustering y reglas de asociación | D13: 2 | E13: 🟢 Comprendido | F13: Sin respuesta que acertar, no se predice. El clustering (agrupamiento) junta datos parecidos. Las reglas de asociación dicen que si pasa algo (antecedente), suele pasar otra cosa (consecuente). Sirven, por ejemplo, para recomendar productos. | H13: Media | I13: 27/09/2026 | J13: 02_tema1_fundamentos_y_preparacion_datos.txt | K13: Sin variable de salida no hay inferencia ni predicción. Clustering: crear grupos de datos similares. Reglas de asociación: reglas antecedente-consecuente que asocian variables, útiles para dependencias y recomendación. | L13: Cesta de la compra: si compra pan y leche (antecedente), suele comprar mantequilla (consecuente). | M13: Un grupo hallado por clustering no trae nombre: el significado lo pone la persona. | N13: ¿Por qué agrupar clientes por parecido no basta para saber qué grupo es el de los que se irán? | O13: 02 §2; PDF p.16.
A14: 1.2.c | B14: 1. Fundamentos y preparación de datos | C14: Reducción de dimensionalidad | D14: 2 | E14: 🟢 Comprendido | F14: Consiste en achicar la cantidad de datos, quitando filas o columnas o transformando los valores, para que el trabajo sea más rápido sin perder calidad. Puede hacerse con o sin una respuesta conocida en los datos. | H14: Media | I14: 27/09/2026 | J14: 02_tema1_fundamentos_y_preparacion_datos.txt | K14: Reduce el volumen de datos antes de modelar, eliminando filas o columnas o transformando el espacio de valores, para mantener o mejorar la eficacia y aumentar la eficiencia. Puede ser supervisada o no supervisada. | L14: Seleccionar las 10 columnas más relacionadas con la clase antes de entrenar un KNN. | M14: Reducir sin criterio puede perder justo la información útil. | N14: ¿Qué dos formas hay de reducir la dimensionalidad? | O14: 02 §2; PDF p.16.
A15: 1.2.d | B15: 1. Fundamentos y preparación de datos | C15: Aprendizaje semisupervisado | D15: 2 | E15: 🟢 Comprendido | F15: Los datos tienen una respuesta a acertar, pero solo en algunas filas. En lugar de borrar las filas que no la tienen, se usan modelos que aprovechan todos los datos disponibles, así no se desperdicia información. | H15: Baja | I15: 27/09/2026 | J15: 02_tema1_fundamentos_y_preparacion_datos.txt | K15: Hay variable de salida, pero no todas las filas tienen valor. En vez de eliminar las filas sin valor, se construyen modelos que aprovechan todas. | L15: 1000 fotos, de las cuales solo 100 tienen su etiqueta confirmada. | M15: Se diferencia del supervisado puro, que exige salida en todas las filas. | N15: ¿Qué problema evita el semisupervisado que el supervisado puro no resuelve? | O15: 02 §2; PDF p.16-17.
A16: 1.2.e | B16: 1. Fundamentos y preparación de datos | C16: Aprendizaje por refuerzo | D16: 2 | E16: 🟢 Comprendido | F16: El algoritmo no recibe la respuesta correcta exacta, sino una valoración de si lo que respondió estuvo bien o mal. Si acierta, se parece al supervisado; si falla, solo sabe que su respuesta no fue adecuada. | H16: Baja | I16: 27/09/2026 | J16: 02_tema1_fundamentos_y_preparacion_datos.txt | K16: El aprendiz recibe una valoración sobre la idoneidad de su respuesta. Con respuestas correctas se parece al supervisado; con errores solo se informa que fue inadecuada, a veces con una estimación del error, no el valor exacto de la respuesta correcta. | L16: Un agente que aprende a jugar recibe puntos o castigos, no la jugada correcta. | M16: En supervisado se puede calcular el error exacto; en refuerzo no necesariamente. | N16: ¿Qué recibe el aprendiz en refuerzo cuando se equivoca, a diferencia del supervisado? | O16: 02 §2; PDF p.17.
A17: 1.2.f | B17: 1. Fundamentos y preparación de datos | C17: Frontera de decisión / frontera bayesiana | D17: 2 | E17: 🟡 Repasar | F17: La frontera de decisión es la línea que separa un grupo de otro. En el caso ideal, si se conocen las reglas exactas de los datos, se calcula la mejor frontera. En la práctica solo hay una muestra, y la frontera estimada mejora cuantos más datos haya. | H17: Media | I17: 27/09/2026 | J17: 02_tema1_fundamentos_y_preparacion_datos.txt | K17: Frontera de decisión: lugar donde el clasificador cambia de una clase a otra. Caso ideal: si se conocen las distribuciones de origen, la frontera óptima (bayesiana) se calcula analíticamente. Caso real: solo hay una muestra y la frontera se estima; mejora con más datos (el notebook compara 10, 100 y 10000 puntos). | L17: Notebook: LogisticRegression (frontera lineal), RandomForestClassifier y SVC sobre los mismos datos 2D. | M17: Todo algoritmo asume algo (normalidad, independencia, forma lineal o cuadrática de la frontera). | N17: ¿Por qué la frontera estimada con 10 puntos suele ser peor que con 10000? | O17: 02 §2 (complemento del notebook de terminología).
A18: 1.3 | B18: 1. Fundamentos y preparación de datos | C18: Estructura de datos: instancias, atributos y clase | D18: 1 | E18: 🟢 Comprendido | F18: Los datos se organizan en una tabla: cada fila es una instancia (un caso) y cada columna es un atributo (un dato descriptivo). Además está la clase, que es la respuesta a predecir. Se anotan como X (atributos) e y (clase). | G18: Practicar identificando instancias, atributos y clase en un dataset real como iris o penguins. | H18: Alta | I18: 27/09/2026 | J18: 02_tema1_fundamentos_y_preparacion_datos.txt | K18: La estructura fundamental es la tabla de datos (dataset): dos dimensiones, columnas de un solo tipo cada una. Cada celda es numérica (float) o categórica (cadena, booleano, entero). Nomenclatura: instancia = fila; atributo = columna de entrada; clase = salida; modelo = lo que extrae el algoritmo. | L18: Iris: 150 instancias, 4 atributos numéricos (sepal-length, sepal-width, petal-length, petal-width), clase con 3 valores, 0 ausentes. | M18: Existen otras estructuras (grafos, series temporales, secuencias, jerarquías) que el curso no desarrolla aquí. | N18: En una tabla de pacientes, ¿qué columna sería la clase y cuáles los atributos? | O18: 02 §3; PDF p.17-19.
A19: 1.3.a | B19: 1. Fundamentos y preparación de datos | C19: Instancia | D19: 2 | E19: 🟢 Comprendido | F19: Es cada fila de la tabla de datos, o sea un caso individual. También se le llama ejemplo, muestra, observación o punto. Por ejemplo, una persona o una flor dentro de la tabla. | H19: Alta | I19: 27/09/2026 | J19: 02_tema1_fundamentos_y_preparacion_datos.txt | K19: Instancia = cada fila de la tabla (también ejemplo, muestra, observación, punto o prototipo; en inglés instance, data point, sample). | L19: Una flor concreta del dataset iris. | M19: No es lo mismo que una característica: la instancia es la fila entera. | N19: Si la tabla tiene 150 filas, ¿cuántas instancias hay? | O19: 02 §3; PDF p.18.
A20: 1.3.b | B20: 1. Fundamentos y preparación de datos | C20: Atributo / característica | D20: 2 | E20: 🟢 Comprendido | F20: Es cada columna de la tabla, excepto la que tiene la respuesta. Describe una característica de cada caso. También se le llama característica, feature, variable de entrada o predictora. | H20: Alta | I20: 27/09/2026 | J20: 02_tema1_fundamentos_y_preparacion_datos.txt | K20: Atributo = cada columna excepto la clase (también característica, causa, variable de entrada, variable explicativa; attribute, feature, predictor). El notebook los usa indistintamente: 'atributo' y 'característica'. | L20: sepal-length y petal-width en iris. | M20: Un atributo medido después del resultado (por ejemplo la nota final) no sirve para predecir con antelación. | N20: ¿Por qué un atributo registrado después del resultado puede ser inútil en la práctica? | O20: 02 §3; PDF p.18.
A21: 1.3.c | B21: 1. Fundamentos y preparación de datos | C21: Clase / variable objetivo | D21: 2 | E21: 🟢 Comprendido | F21: Es la respuesta que se quiere predecir en el aprendizaje supervisado. También se llama etiqueta, target o respuesta. Es un número en regresión y una categoría en clasificación. | H21: Alta | I21: 27/09/2026 | J21: 02_tema1_fundamentos_y_preparacion_datos.txt | K21: Clase = variable de salida del aprendizaje supervisado (también etiqueta, variable objetivo, respuesta, efecto, consecuencia; class, target, response). Numérica en regresión (y_i real) y categórica en clasificación (dominio {c1,...,cm}). | L21: La columna especie de iris, con dominio {setosa, versicolor, virginica}. | M21: Una clase con códigos numéricos sigue siendo categórica. | N21: ¿Cuál es la clase si quieres predecir si un cliente comprará? | O21: 02 §3; PDF p.18.
A22: 1.3.d | B22: 1. Fundamentos y preparación de datos | C22: Notación formal X, y, eᵢ, xⱼ, xᵢⱼ | D22: 2 | E22: 🟡 Repasar | F22: Es la forma de escribir la tabla con símbolos: X guarda todos los atributos de las n instancias (p atributos por instancia); y es la lista de respuestas; eᵢ es la fila i; xⱼ es la columna j; xᵢⱼ es el valor de la columna j en la fila i. | H22: Alta | I22: 27/09/2026 | J22: 02_tema1_fundamentos_y_preparacion_datos.txt | K22: La tabla tiene n instancias y p atributos. X = matriz de atributos; y = vector de clase; e_i = instancia (fila) i; x_j = atributo (columna) j; x_ij = valor del atributo j en la instancia i (i = 1..n, j = 1..p). En programación: X (matriz o DataFrame) e y (vector). | L22: Con 150 filas y 4 columnas, X tiene forma (150, 4) e y tiene forma (150,). | M22: No confundir x_ij (un valor) con x_j (toda la columna) ni con e_i (toda la fila). | N22: ¿Qué representa x_(3,2) en una tabla de pacientes? | O22: 02 §3; PDF p.18-19 (Tabla 1).
A23: 1.3.e | B23: 1. Fundamentos y preparación de datos | C23: Parámetros vs. hiperparámetros | D23: 2 | E23: 🟢 Comprendido | F23: Los parámetros son valores del modelo que se ajustan solos mientras aprende. Los hiperparámetros son ajustes del método de aprendizaje que la persona fija antes de empezar y que no cambian durante el entrenamiento. | H23: Media | I23: 27/09/2026 | J23: 02_tema1_fundamentos_y_preparacion_datos.txt | K23: Parámetros: pertenecen al modelo y se ajustan durante el entrenamiento. Hiperparámetros: pertenecen al algoritmo de aprendizaje, se fijan antes de entrenar y permanecen constantes durante él. Otros términos del notebook: datos de entrenamiento, datos de prueba (test) y métrica. | L23: Parámetro: el coeficiente w1 de una regresión. Hiperparámetro: el número de vecinos k de un KNN. | M23: Los hiperparámetros se eligen con validación, nunca mirando el test. | N23: ¿El número de vecinos k es un parámetro o un hiperparámetro? | O23: 02 §3 (complemento del notebook de terminología).
A24: 1.3.f | B24: 1. Fundamentos y preparación de datos | C24: Características de un conjunto de datos | D24: 2 | E24: 🟡 Repasar | F24: Al empezar un proyecto se anota un resumen de los datos: cuántas filas y columnas hay, de qué tipo es cada columna y la respuesta, y cuántos valores faltan. Ejemplo, iris: 150 instancias, 4 atributos, 3 clases, 0 faltantes. | H24: Baja | I24: 27/09/2026 | J24: 02_tema1_fundamentos_y_preparacion_datos.txt | K24: Al inicio de un proyecto se anota: número de instancias, número de atributos, nombre, tipo y breve descripción de cada atributo, tipo y dominio de la clase, descripción de la clase y cantidad de valores ausentes. | L24: Iris: 150 instancias, 4 atributos numéricos, clase categórica de 3 valores, 0 ausentes. | M24: Una ficha incompleta oculta problemas (ausentes, tipos mal leídos) que aparecen tarde. | N24: ¿Qué cinco datos anotarías de una tabla nueva antes de modelar? | O24: 02 §3; PDF p.19.
A25: 1.4 | B25: 1. Fundamentos y preparación de datos | C25: Limpieza de datos — introducción | D25: 1 | E25: 🟢 Comprendido | F25: Es una tarea clave dentro de la preparación de datos: quita defectos y ajusta los datos para que sus patrones se vean con la mayor claridad posible. Se hace antes de entrenar el modelo para que aprenda de datos limpios. | G25: Repasar junto con las 4 técnicas concretas (normalización, outliers, imputación, selección) que desarrollan esta fase. | H25: Media | I25: 27/09/2026 | J25: 02_tema1_fundamentos_y_preparacion_datos.txt | K25: Eliminación de defectos de los datos y adaptación para el modelado, dentro de la fase de preparación de CRISP-DM. Busca la forma de los datos que exponga sus patrones con más nitidez. El manual estudia: normalización y estandarización, outliers, imputación y selección de atributos; menciona sin desarrollar la discretización, la generación de atributos y la selección de instancias. | L25: Pipeline típico: imputar, escalar y seleccionar atributos, siempre ajustado con entrenamiento. | M25: La limpieza puede ser supervisada o no supervisada según use o no la clase. | N25: ¿Por qué se considera la limpieza parte de la preparación y no del modelado? | O25: 02 §4; PDF p.19-20.
A26: 1.4.a | B26: 1. Fundamentos y preparación de datos | C26: Técnicas de fila, columna o matriz completa | D26: 2 | E26: 🟡 Repasar | F26: Las técnicas de limpieza se clasifican según la parte de la tabla que modifican: una fila, una columna (como la normalización, que cambia una columna entera) o la tabla completa. | H26: Baja | I26: 27/09/2026 | J26: 02_tema1_fundamentos_y_preparacion_datos.txt | K26: Según la parte de la tabla sobre la que actúan: técnicas de fila, de columna o de matriz completa. La normalización es una técnica de columna porque actúa sobre todos los valores de una columna a la vez. | L26: Imputar actúa por columna; eliminar duplicados actúa sobre filas. | M26: Es una clasificación de apoyo; no cambia cómo se calcula cada técnica. | N26: ¿La normalización es una técnica de fila, de columna o de matriz completa? | O26: 02 §4; PDF p.20.
A27: 1.4.b | B27: 1. Fundamentos y preparación de datos | C27: Limpieza supervisada vs. no supervisada | D27: 2 | E27: 🟢 Comprendido | F27: Igual que en el aprendizaje automático, algunas técnicas de limpieza necesitan que los datos incluyan la respuesta a predecir (la clase) y otras funcionan sin ella. | H27: Baja | I27: 27/09/2026 | J27: 02_tema1_fundamentos_y_preparacion_datos.txt | K27: Como en el aprendizaje automático, las técnicas de limpieza pueden ser supervisadas (usan la clase) o no supervisadas (no la usan). | L27: Baja varianza: no supervisada. F-test: supervisada. | M27: Una técnica supervisada que usa la clase de todo el conjunto antes de separar test provoca fuga de información. | N27: ¿Por qué una selección supervisada debe ajustarse solo con entrenamiento? | O27: 02 §4; PDF p.20.
A28: 1.5 | B28: 1. Fundamentos y preparación de datos | C28: Normalización y estandarización | D28: 1 | E28: 🟢 Comprendido | F28: Son dos técnicas para poner los datos numéricos en una escala parecida. Se hace para que una columna con números muy grandes no pese más que otra igual de importante. Normalización: (x − mínimo)/(máximo − mínimo). Estandarización: (x − media)/desviación. | G28: Practicar aplicando MinMaxScaler y StandardScaler con fit en train y transform en test. | H28: Alta | I28: 27/09/2026 | J28: 02_tema1_fundamentos_y_preparacion_datos.txt | K28: Normalización: lleva cada atributo numérico a [0,1] con x_N = (x - min) / (max - min) (centrado y escalado por el rango). Estandarización: x_S = (x - media) / desviación típica (centrado en la media y escalado por la desviación). Se aplican columna por columna. | L28: X_train = [[1,-1,2],[2,0,0],[0,1,-1]]; MinMaxScaler().fit_transform(X_train) da [[0.5,0,1],[1,0.5,0.333],[0,1,0]]. | M28: Ajusta (fit) con entrenamiento y aplica (transform) a test sin reajustar. | N28: ¿Qué problema evitan ambas técnicas cuando se usan distancias entre casos? | O28: 02 §5; PDF p.20-22.
A29: 1.5.a | B29: 1. Fundamentos y preparación de datos | C29: Normalización | D29: 2 | E29: 🟢 Comprendido | F29: Lleva los valores de una columna al rango de 0 a 1: se resta el menor valor y se divide por la diferencia entre el mayor y el menor. Se aplica columna por columna. Así todas quedan en la misma escala. | H29: Alta | I29: 27/09/2026 | J29: 02_tema1_fundamentos_y_preparacion_datos.txt | K29: x_N = (x - min(x_i)) / (max(x_i) - min(x_i)). Restar el mínimo = centrado; dividir por el rango = escalado. Para desnormalizar: x = x_N (max - min) + min. Es una homotecia aplicada a cada columna. | L29: Un atributo con mínimo 0 y máximo 2: 0 pasa a 0, 1 pasa a 0,5 y 2 pasa a 1. Clase: preprocessing.MinMaxScaler. | M29: Con datos futuros fuera del rango de entrenamiento el resultado puede salir de [0,1]; y si max = min la fórmula no está definida. | N29: Si el máximo de entrenamiento es 60 y llega un caso con 70, ¿cuánto vale su normalizado con mínimo 20? | O29: 02 §5; PDF p.20-21 (Programa 1).
A30: 1.5.b | B30: 1. Fundamentos y preparación de datos | C30: Estandarización | D30: 2 | E30: 🟢 Comprendido | F30: Ajusta una columna para que quede centrada en su promedio (media) y medida según cuánto se alejan los valores de él (desviación típica). A diferencia de la normalización, los valores no quedan limitados a un rango fijo. | H30: Alta | I30: 27/09/2026 | J30: 02_tema1_fundamentos_y_preparacion_datos.txt | K30: x_S = (x - media(x_i)) / desviación(x_i). El escalado cubre solo la amplitud de la desviación típica, por lo que los valores no quedan acotados a un rango fijo. Desestandarizar: x = x_S desv + media. | L30: Primer atributo del ejemplo del PDF: media 1, desviación 0,8165; el valor 2 pasa a (2-1)/0,8165 = 1,22474. Clase: preprocessing.StandardScaler. | M30: Si la desviación es cero la fórmula exige un tratamiento especial. | N30: Si un valor estandarizado es 0, ¿qué significa respecto a la media? | O30: 02 §5; PDF p.22 (Programa 2).
A31: 1.5.c | B31: 1. Fundamentos y preparación de datos | C31: Cuándo usar cada técnica | D31: 2 | E31: 🟢 Comprendido | F31: Se usa normalización cuando el algoritmo no supone nada sobre cómo se reparten los valores. Se usa estandarización cuando el algoritmo sí supone que los datos siguen la forma de campana (distribución normal). | H31: Media | I31: 27/09/2026 | J31: 02_tema1_fundamentos_y_preparacion_datos.txt | K31: Criterio práctico del notebook: normalización para algoritmos que no presuponen una distribución de los datos; estandarización cuando el algoritmo sí presupone normalidad. Ambas son muy recomendables si se usan distancias o productos escalares. | L31: KNN (basado en distancias) suele necesitar estandarizar; un árbol de decisión es independiente de la escala. | M31: Cambiar la escala no vuelve relevante un atributo que no lo era. | N31: ¿Qué técnica elegirías si el algoritmo supone datos con distribución normal? | O31: 02 §5 (notebook limpieza_datos_1).
A32: 1.5.d | B32: 1. Fundamentos y preparación de datos | C32: Evitar fuga de información (data leakage) | D32: 2 | E32: 🟢 Comprendido | F32: Al separar los datos en entrenamiento (train) y prueba (test), la transformación se calcula solo con los de entrenamiento y luego se aplica igual a los de prueba, sin recalcularla. Así la prueba no "espía" información que el modelo no debería conocer. | H32: Alta | I32: 27/09/2026 | J32: 02_tema1_fundamentos_y_preparacion_datos.txt | K32: Al dividir en train y test, el normalizador o estandarizador se ajusta (fit) solo con train y se aplica (transform) tal cual a test; nunca se reajusta con test. Así el test no influye en la preparación del modelo (fuga de información o data leakage). | L32: f = normalizer.fit(X_train); X_train_n = f.transform(X_train); X_test_n = f.transform(X_test) (sin fit). | M32: Calcular el mínimo y el máximo con toda la tabla antes de separar contamina el test. | N32: ¿Por qué calcular la media con todos los datos antes de separar el test deja de ser una prueba independiente? | O32: 02 §5 (notebook); 03 §0.
A33: 1.6 | B33: 1. Fundamentos y preparación de datos | C33: Detección de outliers | D33: 1 | E33: 🟢 Comprendido | F33: Un outlier es un dato muy raro frente al resto, y puede confundir a los modelos y bajar su calidad. Esta etapa busca esos casos. No hay una línea exacta que separe lo raro de lo normal, así que el límite suele ser difuso. | G33: Practicar EllipticEnvelope y el método boxplot sobre el dataset outliers.csv. | H33: Alta | I33: 27/09/2026 | J33: 02_tema1_fundamentos_y_preparacion_datos.txt | K33: Un outlier es un valor fuera de la distribución natural de los datos que puede reducir la eficacia de los modelos. El umbral entre outlier y no-outlier no es trivial: la frontera suele ser difusa. El manual desarrolla un algoritmo (envolvente elíptica); el notebook añade el método de cajas y bigotes y otros detectores. | L33: outliers.csv: 200 instancias, 2 atributos, 150 normales y 50 outliers, rango [-7, 7]. | M33: Un valor extremo puede ser un error o un caso real: investígalo antes de borrarlo. | N33: ¿Por qué encontrar un valor sorprendente no demuestra por sí solo que deba eliminarse? | O33: 02 §6; PDF p.23-26.
A34: 1.6.a | B34: 1. Fundamentos y preparación de datos | C34: Envolvente elíptica (EllipticEnvelope) | D34: 2 | E34: 🟢 Comprendido | F34: Supone que los datos se reparten como una campana: muchos en el centro y pocos lejos. Dibuja una elipse (óvalo) alrededor de los puntos normales. Mientras más grande es la elipse que hace falta para incluir un punto, más lejos está y más probable es que sea un outlier. Se usa con sklearn.covariance.EllipticEnvelope. | H34: Alta | I34: 27/09/2026 | J34: 02_tema1_fundamentos_y_preparacion_datos.txt | K34: EllipticEnvelope: supone distribución normal; crea superficies elípticas alrededor de los puntos normales; cuanto mayor la elipse que engloba un punto, mayor su distancia y su probabilidad de ser outlier. Los datos se centran y escalan con mediana e IQR. | L34: EllipticEnvelope().fit(df); decision_function(df) puntúa la normalidad de cada instancia. | M34: Si los datos no son normales puede haber falsos positivos y falsos negativos. | N34: ¿Qué supuesto sobre la distribución hace la envolvente elíptica? | O34: 02 §6; PDF p.24-26 (Programa 3).
A35: 1.6.b | B35: 1. Fundamentos y preparación de datos | C35: Mediana e IQR como base del cálculo | D35: 2 | E35: 🟢 Comprendido | F35: El centro de las elipses se calcula con la mediana (el valor del medio) y el IQR (el ancho de la zona donde está la mitad central de los datos), no con el promedio. El motivo: los propios outliers deforman el promedio. IQR = P75 - P25; umbral típico: mediana ± 1,5·IQR o ± 3·IQR. | H35: Media | I35: 27/09/2026 | J35: 02_tema1_fundamentos_y_preparacion_datos.txt | K35: Se usa la mediana en vez de la media porque la media se distorsiona con los propios outliers. IQR = P75 - P25. Todo valor que supere la mediana más o menos un umbral (típicamente 1,5 IQR, moderado, o 3 IQR, extremo) se considera outlier. | L35: Q1 = scoreatpercentile(a, 25); Q3 = scoreatpercentile(a, 75); IQR = Q3 - Q1. | M35: 1,5 IQR y 3 IQR son convenciones, no verdades: cambian cuántos puntos se marcan. | N35: ¿Por qué la mediana resiste mejor a los outliers que la media? | O35: 02 §6; PDF p.24.
A36: 1.6.c | B36: 1. Fundamentos y preparación de datos | C36: Umbral por percentil vs. contamination fijo | D36: 2 | E36: 🟢 Comprendido | F36: Hay dos formas de decidir qué es raro con la misma herramienta. El PDF puntúa cada dato y corta en un percentil (25). El notebook fija de antemano que 25% de los datos serán outliers (contamination=0.25). Cambia solo cómo se pone el corte. | H36: Media | I36: 27/09/2026 | J36: 02_tema1_fundamentos_y_preparacion_datos.txt | K36: Versión PDF: decision_function() puntúa la normalidad y scoreatpercentile(scores_pred, 25) fija el umbral en el percentil 25. Versión notebook: EllipticEnvelope(support_fraction=None, contamination=0.25, random_state=42) y predict() devuelve 1 (normal) o -1 (outlier). Es la misma clase con distinta forma de fijar el corte. | L36: pos_outliers = np.where(predict(df) == -1)[0] da las posiciones de los outliers. | M36: contamination fija de antemano la proporción esperada de outliers: si es incorrecta, el resultado también. | N36: ¿Qué proporción de outliers asume contamination=0.25? | O36: 02 §6 (PDF p.25-26 y notebook limpieza_datos_1).
A37: 1.6.d | B37: 1. Fundamentos y preparación de datos | C37: Método boxplot / cajas y bigotes | D37: 2 | E37: 🔴 Débil | F37: Método solo del notebook, el de cajas y bigotes. Calcula dónde empieza y termina la mitad central de los datos (Q1, Q3, IQR) y marca como outlier todo lo que cae fuera de unos límites. Límite superior = P75+1.5·IQR; límite inferior = P25-1.5·IQR. | H37: Media | I37: 27/09/2026 | J37: 02_tema1_fundamentos_y_preparacion_datos.txt | K37: Método solo del notebook: Q1 = P25, Q3 = P75, RIC = Q3 - Q1. Límite superior = Q3 + 1,5 RIC; límite inferior = Q1 - 1,5 RIC. Se marca outlier lo que cae fuera. Se dibuja con plt.boxplot. | L37: pos_i = np.where(a < li)[0]; pos_s = np.where(a > ls)[0]; pos_outliers = np.concatenate((pos_i, pos_s)). | M37: No está desarrollado en el PDF; solo el concepto de IQR coincide con la envolvente elíptica. | N37: ¿Con qué fórmula se obtiene el límite superior del boxplot? | O37: 02 §6 (solo notebook).
A38: 1.6.e | B38: 1. Fundamentos y preparación de datos | C38: Otros detectores de outliers | D38: 2 | E38: 🔴 Débil | F38: Existen otras herramientas de sklearn para encontrar datos raros: IsolationForest, LocalOutlierFactor y OneClassSVM. Se usan igual que la anterior: primero se ajustan a los datos (fit) y luego marcan cuáles son raros (predict). | H38: Baja | I38: 27/09/2026 | J38: 02_tema1_fundamentos_y_preparacion_datos.txt | K38: Otros detectores de sklearn con el mismo patrón fit y predict: IsolationForest, LocalOutlierFactor, OneClassSVM (se plantean como ejercicio de comparación). | L38: IF = IsolationForest(); df_outliers, pos_outliers = find_outliers(df, IF). | M38: El notebook solo los menciona; no se explica su fundamento. | N38: ¿Qué tienen en común los detectores de outliers de sklearn en cuanto a su uso? | O38: 02 §6 (notebook).
A39: 1.7 | B39: 1. Fundamentos y preparación de datos | C39: Imputación de valores ausentes | D39: 1 | E39: 🔴 Débil | F39: Cuando faltan datos (huecos o NaN), en vez de borrar los registros completos se rellenan con valores estimados. Así se evita perder la información que sí estaba en esos registros. | G39: Practicar SimpleImputer sobre datos reales (penguins.csv) con fit/transform. | H39: Alta | I39: 27/09/2026 | J39: 02_tema1_fundamentos_y_preparacion_datos.txt | K39: Los conjuntos de datos suelen estar incompletos (valores ausentes o missing values; en Python np.nan). Muchos algoritmos de scikit-learn no toleran ausentes. Eliminar las instancias con algún ausente puede perder mucha información; por eso se imputa (se reemplaza por un valor estimado). | L39: SimpleImputer(missing_values=np.nan, strategy='mean'). | M39: Calcula el valor de relleno solo con entrenamiento y aplica el mismo a test. | N39: ¿Por qué borrar todas las filas con ausentes puede ser una mala idea? | O39: 02 §7; PDF p.26-28.
A40: 1.7.a | B40: 1. Fundamentos y preparación de datos | C40: Valores ausentes (missing values) | D40: 2 | E40: 🟢 Comprendido | F40: Son huecos en los datos: la información no se recogió, no estaba disponible, o era errónea y se borró. En Python se marcan con np.nan, que significa 'no es un número'. | H40: Media | I40: 27/09/2026 | J40: 02_tema1_fundamentos_y_preparacion_datos.txt | K40: Valores ausentes: huecos porque la información no pudo recabarse, no estaba disponible o era errónea y se eliminó. Se representan como NaN, NA, N/A o Null; en Python con np.nan. | L40: csv.isna().sum() cuenta los ausentes por columna del dataset penguins. | M40: Un ausente puede significar cosas distintas (no aplica, no se midió, se perdió): averígualo antes de imputar. | N40: ¿Qué función cuenta los valores ausentes por columna en pandas? | O40: 02 §7; PDF p.26.
...
