Workbook

Sheet Resumen
A1: RAZONAMIENTO APROXIMADO — SEGUIMIENTO DE ESTUDIO
A3: Actualización: Probabilidad Bayesiana 1.3 ya está INICIADA; las cuatro variables base quedaron comprendidas.
A5: Total conceptos | C5: Comprendidos / firmes | E5: Pendientes | G5: Débiles
A6: =COUNTA('Mapa de estudio'!$A$2:$A$171) -> 170 | C6: =COUNTIF('Mapa de estudio'!$E$2:$E$171,"🟢 Comprendido")+COUNTIF('Mapa de estudio'!$E$2:$E$171,"🟢 Firme") -> 100 | E6: =COUNTIF('Mapa de estudio'!$E$2:$E$171,"⚪ Pendiente") -> 23 | G6: =COUNTIF('Mapa de estudio'!$E$2:$E$171,"🔴 Débil") -> 2
A9: Estado | B9: Cantidad | D9: DETALLE DEL CONCEPTO EN CURSO — 1.3 PROBABILIDAD BAYESIANA (ver tabla completa en J:N)
A10: 🟢 Firme | B10: =COUNTIF('Mapa de estudio'!$E$2:$E$171,A10) -> 9 | D10: Concepto | E10: Estado | F10: Idea clave | G10: Siguiente | H10: Prioridad
A11: 🟢 Comprendido | B11: =COUNTIF('Mapa de estudio'!$E$2:$E$171,A11) -> 91 | D11: h = hipótesis | E11: =INDEX('Mapa de estudio'!$E$2:$E$171,MATCH("1.3.a",'Mapa de estudio'!$A$2:$A$171,0)) -> 🟢 Comprendido | F11: =INDEX('Mapa de estudio'!$F$2:$F$171,MATCH("1.3.a",'Mapa de estudio'!$A$2:$A$171,0)) -> Conceptualmente, es la afirmación que quiero comprobar. Ej: «quien llama es mi amigo». | G11: =INDEX('Mapa de estudio'!$G$2:$G$171,MATCH("1.3.a",'Mapa de estudio'!$A$2:$A$171,0))&"" | H11: =INDEX('Mapa de estudio'!$H$2:$H$171,MATCH("1.3.a",'Mapa de estudio'!$A$2:$A$171,0)) -> Baja
A12: 🟡 Repasar | B12: =COUNTIF('Mapa de estudio'!$E$2:$E$171,A12) -> 35 | D12: e = evidencia | E12: =INDEX('Mapa de estudio'!$E$2:$E$171,MATCH("1.3.b",'Mapa de estudio'!$A$2:$A$171,0)) -> 🟢 Comprendido | F12: =INDEX('Mapa de estudio'!$F$2:$F$171,MATCH("1.3.b",'Mapa de estudio'!$A$2:$A$171,0)) -> Conceptualmente, es el dato nuevo que observo y que puede cambiar lo que creo sobre h. Ej: «se oye tráfico». | G12: =INDEX('Mapa de estudio'!$G$2:$G$171,MATCH("1.3.b",'Mapa de estudio'!$A$2:$A$171,0))&"" | H12: =INDEX('Mapa de estudio'!$H$2:$H$171,MATCH("1.3.b",'Mapa de estudio'!$A$2:$A$171,0)) -> Baja
A13: 🟠 Iniciado | B13: =COUNTIF('Mapa de estudio'!$E$2:$E$171,A13) -> 8 | D13: P(h) | E13: =INDEX('Mapa de estudio'!$E$2:$E$171,MATCH("1.3.c",'Mapa de estudio'!$A$2:$A$171,0)) -> 🟢 Comprendido | F13: =INDEX('Mapa de estudio'!$F$2:$F$171,MATCH("1.3.c",'Mapa de estudio'!$A$2:$A$171,0)) -> Conceptualmente, es cuánto creo en h antes de ver la evidencia e. | G13: =INDEX('Mapa de estudio'!$G$2:$G$171,MATCH("1.3.c",'Mapa de estudio'!$A$2:$A$171,0))&"" | H13: =INDEX('Mapa de estudio'!$H$2:$H$171,MATCH("1.3.c",'Mapa de estudio'!$A$2:$A$171,0)) -> Baja
A14: 🟠 Parcial | B14: =COUNTIF('Mapa de estudio'!$E$2:$E$171,A14) -> 2 | D14: P(h|e) | E14: =INDEX('Mapa de estudio'!$E$2:$E$171,MATCH("1.3.d",'Mapa de estudio'!$A$2:$A$171,0)) -> 🟢 Comprendido | F14: =INDEX('Mapa de estudio'!$F$2:$F$171,MATCH("1.3.d",'Mapa de estudio'!$A$2:$A$171,0)) -> Conceptualmente, es cuánto creo en h después de ver e (la barra «|» se lee «dado que»). | G14: =INDEX('Mapa de estudio'!$G$2:$G$171,MATCH("1.3.d",'Mapa de estudio'!$A$2:$A$171,0))&"" | H14: =INDEX('Mapa de estudio'!$H$2:$H$171,MATCH("1.3.d",'Mapa de estudio'!$A$2:$A$171,0)) -> Baja
A15: ⚪ Pendiente | B15: =COUNTIF('Mapa de estudio'!$E$2:$E$171,A15) -> 23 | D15: P(e|h) | E15: =INDEX('Mapa de estudio'!$E$2:$E$171,MATCH("1.3.f",'Mapa de estudio'!$A$2:$A$171,0)) -> 🟢 Comprendido | F15: =INDEX('Mapa de estudio'!$F$2:$F$171,MATCH("1.3.f",'Mapa de estudio'!$A$2:$A$171,0)) -> Conceptualmente, es qué tan esperable sería ver la evidencia e si la hipótesis h fuera cierta. Ej: si llama mi amigo de la calle, oír tráfico es muy esperable. | G15: =INDEX('Mapa de estudio'!$G$2:$G$171,MATCH("1.3.f",'Mapa de estudio'!$A$2:$A$171,0))&"" -> Explicarlo antes de usar la fórmula. | H15: =INDEX('Mapa de estudio'!$H$2:$H$171,MATCH("1.3.f",'Mapa de estudio'!$A$2:$A$171,0)) -> Alta
A16: 🔴 Débil | B16: =COUNTIF('Mapa de estudio'!$E$2:$E$171,A16) -> 2 | D16: P(e) | E16: =INDEX('Mapa de estudio'!$E$2:$E$171,MATCH("1.3.g",'Mapa de estudio'!$A$2:$A$171,0)) -> 🟢 Comprendido | F16: =INDEX('Mapa de estudio'!$F$2:$F$171,MATCH("1.3.g",'Mapa de estudio'!$A$2:$A$171,0)) -> Conceptualmente, es qué tan común es ver la evidencia e en total (con h y sin h); sirve de divisor para que el resultado quede entre 0 y 1. | G16: =INDEX('Mapa de estudio'!$G$2:$G$171,MATCH("1.3.g",'Mapa de estudio'!$A$2:$A$171,0))&"" -> Explicarlo junto con P(e|h) sin mezclar ambos. | H16: =INDEX('Mapa de estudio'!$H$2:$H$171,MATCH("1.3.g",'Mapa de estudio'!$A$2:$A$171,0)) -> Alta
D17: Teorema de Bayes | E17: =INDEX('Mapa de estudio'!$E$2:$E$171,MATCH("1.3.h",'Mapa de estudio'!$A$2:$A$171,0)) -> 🟢 Comprendido | F17: =INDEX('Mapa de estudio'!$F$2:$F$171,MATCH("1.3.h",'Mapa de estudio'!$A$2:$A$171,0)) -> Conceptualmente, es la regla que calcula la creencia nueva: mi creencia inicial ajustada por qué tan esperable era la evidencia, dividida entre qué tan común es esa evidencia. Fórmula: P(h|e) = P(h)·P(e|h) / P(e). | G17: =INDEX('Mapa de estudio'!$G$2:$G$171,MATCH("1.3.h",'Mapa de estudio'!$A$2:$A$171,0))&"" -> Construir la fórmula solo cuando cada término esté entendido. | H17: =INDEX('Mapa de estudio'!$H$2:$H$171,MATCH("1.3.h",'Mapa de estudio'!$A$2:$A$171,0)) -> Alta
J23: TODOS LOS TEMAS DEL CURSO — 50 temas (nivel 1, los 5 bloques)
J24: Código | K24: Bloque | L24: Tema | M24: Estado | N24: Prioridad
J25: ='Mapa de estudio'!A3 -> 1.1 | K25: =LEFT(J25,FIND(".",J25)-1) -> 1 | L25: ='Mapa de estudio'!C3 -> Qué es incertidumbre | M25: ='Mapa de estudio'!E3 -> 🟢 Comprendido | N25: ='Mapa de estudio'!H3 -> Baja
J26: ='Mapa de estudio'!A7 -> 1.2 | K26: =LEFT(J26,FIND(".",J26)-1) -> 1 | L26: ='Mapa de estudio'!C7 -> Incertidumbre vs. borrosidad | M26: ='Mapa de estudio'!E7 -> 🟢 Firme | N26: ='Mapa de estudio'!H7 -> Baja
J27: ='Mapa de estudio'!A10 -> 1.3 | K27: =LEFT(J27,FIND(".",J27)-1) -> 1 | L27: ='Mapa de estudio'!C10 -> Probabilidad Bayesiana | M27: ='Mapa de estudio'!E10 -> 🟢 Comprendido | N27: ='Mapa de estudio'!H10 -> Alta
J28: ='Mapa de estudio'!A23 -> 1.4 | K28: =LEFT(J28,FIND(".",J28)-1) -> 1 | L28: ='Mapa de estudio'!C23 -> Factores de Certeza / MYCIN | M28: ='Mapa de estudio'!E23 -> 🟠 Iniciado | N28: ='Mapa de estudio'!H23 -> Alta
J29: ='Mapa de estudio'!A32 -> 1.5 | K29: =LEFT(J29,FIND(".",J29)-1) -> 1 | L29: ='Mapa de estudio'!C32 -> Dempster-Shafer | M29: ='Mapa de estudio'!E32 -> 🟢 Comprendido | N29: ='Mapa de estudio'!H32 -> Alta
J30: ='Mapa de estudio'!A40 -> 2.1 | K30: =LEFT(J30,FIND(".",J30)-1) -> 2 | L30: ='Mapa de estudio'!C40 -> Qué problema resuelve | M30: ='Mapa de estudio'!E40 -> 🟢 Comprendido | N30: ='Mapa de estudio'!H40 -> Baja
J31: ='Mapa de estudio'!A42 -> 2.2 | K31: =LEFT(J31,FIND(".",J31)-1) -> 2 | L31: ='Mapa de estudio'!C42 -> Fuzzy / difuso | M31: ='Mapa de estudio'!E42 -> 🟢 Comprendido | N31: ='Mapa de estudio'!H42 -> Baja
J32: ='Mapa de estudio'!A43 -> 2.3 | K32: =LEFT(J32,FIND(".",J32)-1) -> 2 | L32: ='Mapa de estudio'!C43 -> Crisp / nítido | M32: ='Mapa de estudio'!E43 -> 🟢 Comprendido | N32: ='Mapa de estudio'!H43 -> Baja
J33: ='Mapa de estudio'!A44 -> 2.4 | K33: =LEFT(J33,FIND(".",J33)-1) -> 2 | L33: ='Mapa de estudio'!C44 -> Fuzzy vs. Crisp | M33: ='Mapa de estudio'!E44 -> 🟢 Firme | N33: ='Mapa de estudio'!H44 -> Baja
J34: ='Mapa de estudio'!A45 -> 2.5 | K34: =LEFT(J34,FIND(".",J34)-1) -> 2 | L34: ='Mapa de estudio'!C45 -> Conjuntos borrosos | M34: ='Mapa de estudio'!E45 -> 🟢 Comprendido | N34: ='Mapa de estudio'!H45 -> Media
J35: ='Mapa de estudio'!A46 -> 2.6 | K35: =LEFT(J35,FIND(".",J35)-1) -> 2 | L35: ='Mapa de estudio'!C46 -> Función de pertenencia μ | M35: ='Mapa de estudio'!E46 -> 🟢 Comprendido | N35: ='Mapa de estudio'!H46 -> Alta
J36: ='Mapa de estudio'!A47 -> 2.7 | K36: =LEFT(J36,FIND(".",J36)-1) -> 2 | L36: ='Mapa de estudio'!C47 -> Grado de pertenencia | M36: ='Mapa de estudio'!E47 -> 🟢 Comprendido | N36: ='Mapa de estudio'!H47 -> Alta
J37: ='Mapa de estudio'!A48 -> 2.8 | K37: =LEFT(J37,FIND(".",J37)-1) -> 2 | L37: ='Mapa de estudio'!C48 -> Universo de discurso | M37: ='Mapa de estudio'!E48 -> 🟢 Comprendido | N37: ='Mapa de estudio'!H48 -> Media
A38: Criterio de avance: un concepto no se marca como dominado solo por haberlo visto. En Bayes, por ahora está validado el significado de h, e, P(h) y P(h|e); la fórmula todavía NO está marcada como aprendida. | J38: ='Mapa de estudio'!A49 -> 2.9 | K38: =LEFT(J38,FIND(".",J38)-1) -> 2 | L38: ='Mapa de estudio'!C49 -> Soporte | M38: ='Mapa de estudio'!E49 -> 🔴 Débil | N38: ='Mapa de estudio'!H49 -> Media
J39: ='Mapa de estudio'!A50 -> 2.10 | K39: =LEFT(J39,FIND(".",J39)-1) -> 2 | L39: ='Mapa de estudio'!C50 -> Núcleo | M39: ='Mapa de estudio'!E50 -> 🟠 Parcial | N39: ='Mapa de estudio'!H50 -> Media
J40: ='Mapa de estudio'!A51 -> 2.11 | K40: =LEFT(J40,FIND(".",J40)-1) -> 2 | L40: ='Mapa de estudio'!C51 -> Altura | M40: ='Mapa de estudio'!E51 -> 🟡 Repasar | N40: ='Mapa de estudio'!H51 -> Media
J41: ='Mapa de estudio'!A52 -> 2.12 | K41: =LEFT(J41,FIND(".",J41)-1) -> 2 | L41: ='Mapa de estudio'!C52 -> α-cortes | M41: ='Mapa de estudio'!E52 -> 🟡 Repasar | N41: ='Mapa de estudio'!H52 -> Media
A42: PROGRESO POR BLOQUE — TODOS LOS TEMAS DEL CURSO | J42: ='Mapa de estudio'!A53 -> 2.13 | K42: =LEFT(J42,FIND(".",J42)-1) -> 2 | L42: ='Mapa de estudio'!C53 -> Cardinalidad | M42: ='Mapa de estudio'!E53 -> 🟡 Repasar | N42: ='Mapa de estudio'!H53 -> Media
A43: Bloque | B43: Total | C43: 🟢 Dominado | D43: 🟠 En progreso | E43: 🟡 Repasar | F43: ⚪ Pendiente | G43: 🔴 Débil | H43: % Dominado | J43: ='Mapa de estudio'!A54 -> 2.14 | K43: =LEFT(J43,FIND(".",J43)-1) -> 2 | L43: ='Mapa de estudio'!C54 -> Operadores borrosos | M43: ='Mapa de estudio'!E54 -> 🟡 Repasar | N43: ='Mapa de estudio'!H54 -> Alta
A44: 1. Modelos clásicos de incertidumbre | B44: =COUNTIF('Mapa de estudio'!$B$2:$B$171,$A44) -> 37 | C44: =COUNTIFS('Mapa de estudio'!$B$2:$B$171,$A44,'Mapa de estudio'!$E$2:$E$171,"🟢 Firme")+COUNTIFS('Mapa de estudio'!$B$2:$B$171,$A44,'Mapa de estudio'!$E$2:$E$171,"🟢 Comprendido") -> 35 | D44: =COUNTIFS('Mapa de estudio'!$B$2:$B$171,$A44,'Mapa de estudio'!$E$2:$E$171,"🟠 Iniciado")+COUNTIFS('Mapa de estudio'!$B$2:$B$171,$A44,'Mapa de estudio'!$E$2:$E$171,"🟠 Parcial") -> 1 | E44: =COUNTIFS('Mapa de estudio'!$B$2:$B$171,$A44,'Mapa de estudio'!$E$2:$E$171,"🟡 Repasar") -> 1 | F44: =COUNTIFS('Mapa de estudio'!$B$2:$B$171,$A44,'Mapa de estudio'!$E$2:$E$171,"⚪ Pendiente") -> 0 | G44: =COUNTIFS('Mapa de estudio'!$B$2:$B$171,$A44,'Mapa de estudio'!$E$2:$E$171,"🔴 Débil") -> 0 | H44: =IFERROR(C44/B44,0) -> 0.94594595 | J44: ='Mapa de estudio'!A60 -> 2.15 | K44: =LEFT(J44,FIND(".",J44)-1) -> 2 | L44: ='Mapa de estudio'!C60 -> Principio de extensión | M44: ='Mapa de estudio'!E60 -> 🟡 Repasar | N44: ='Mapa de estudio'!H60 -> Media
A45: 2. Fundamentos de lógica borrosa | B45: =COUNTIF('Mapa de estudio'!$B$2:$B$171,$A45) -> 26 | C45: =COUNTIFS('Mapa de estudio'!$B$2:$B$171,$A45,'Mapa de estudio'!$E$2:$E$171,"🟢 Firme")+COUNTIFS('Mapa de estudio'!$B$2:$B$171,$A45,'Mapa de estudio'!$E$2:$E$171,"🟢 Comprendido") -> 9 | D45: =COUNTIFS('Mapa de estudio'!$B$2:$B$171,$A45,'Mapa de estudio'!$E$2:$E$171,"🟠 Iniciado")+COUNTIFS('Mapa de estudio'!$B$2:$B$171,$A45,'Mapa de estudio'!$E$2:$E$171,"🟠 Parcial") -> 2 | E45: =COUNTIFS('Mapa de estudio'!$B$2:$B$171,$A45,'Mapa de estudio'!$E$2:$E$171,"🟡 Repasar") -> 14 | F45: =COUNTIFS('Mapa de estudio'!$B$2:$B$171,$A45,'Mapa de estudio'!$E$2:$E$171,"⚪ Pendiente") -> 0 | G45: =COUNTIFS('Mapa de estudio'!$B$2:$B$171,$A45,'Mapa de estudio'!$E$2:$E$171,"🔴 Débil") -> 1 | H45: =IFERROR(C45/B45,0) -> 0.34615385 | J45: ='Mapa de estudio'!A61 -> 2.16 | K45: =LEFT(J45,FIND(".",J45)-1) -> 2 | L45: ='Mapa de estudio'!C61 -> Relaciones borrosas | M45: ='Mapa de estudio'!E61 -> 🟡 Repasar | N45: ='Mapa de estudio'!H61 -> Alta
A46: 3. Razonamiento aproximado | B46: =COUNTIF('Mapa de estudio'!$B$2:$B$171,$A46) -> 28 | C46: =COUNTIFS('Mapa de estudio'!$B$2:$B$171,$A46,'Mapa de estudio'!$E$2:$E$171,"🟢 Firme")+COUNTIFS('Mapa de estudio'!$B$2:$B$171,$A46,'Mapa de estudio'!$E$2:$E$171,"🟢 Comprendido") -> 22 | D46: =COUNTIFS('Mapa de estudio'!$B$2:$B$171,$A46,'Mapa de estudio'!$E$2:$E$171,"🟠 Iniciado")+COUNTIFS('Mapa de estudio'!$B$2:$B$171,$A46,'Mapa de estudio'!$E$2:$E$171,"🟠 Parcial") -> 0 | E46: =COUNTIFS('Mapa de estudio'!$B$2:$B$171,$A46,'Mapa de estudio'!$E$2:$E$171,"🟡 Repasar") -> 6 | F46: =COUNTIFS('Mapa de estudio'!$B$2:$B$171,$A46,'Mapa de estudio'!$E$2:$E$171,"⚪ Pendiente") -> 0 | G46: =COUNTIFS('Mapa de estudio'!$B$2:$B$171,$A46,'Mapa de estudio'!$E$2:$E$171,"🔴 Débil") -> 0 | H46: =IFERROR(C46/B46,0) -> 0.78571429 | J46: ='Mapa de estudio'!A66 -> 3.1 | K46: =LEFT(J46,FIND(".",J46)-1) -> 3 | L46: ='Mapa de estudio'!C66 -> Qué significa razonar aproximadamente | M46: ='Mapa de estudio'!E66 -> 🟢 Comprendido | N46: ='Mapa de estudio'!H66 -> Baja
A47: 4. Control borroso | B47: =COUNTIF('Mapa de estudio'!$B$2:$B$171,$A47) -> 27 | C47: =COUNTIFS('Mapa de estudio'!$B$2:$B$171,$A47,'Mapa de estudio'!$E$2:$E$171,"🟢 Firme")+COUNTIFS('Mapa de estudio'!$B$2:$B$171,$A47,'Mapa de estudio'!$E$2:$E$171,"🟢 Comprendido") -> 9 | D47: =COUNTIFS('Mapa de estudio'!$B$2:$B$171,$A47,'Mapa de estudio'!$E$2:$E$171,"🟠 Iniciado")+COUNTIFS('Mapa de estudio'!$B$2:$B$171,$A47,'Mapa de estudio'!$E$2:$E$171,"🟠 Parcial") -> 3 | E47: =COUNTIFS('Mapa de estudio'!$B$2:$B$171,$A47,'Mapa de estudio'!$E$2:$E$171,"🟡 Repasar") -> 10 | F47: =COUNTIFS('Mapa de estudio'!$B$2:$B$171,$A47,'Mapa de estudio'!$E$2:$E$171,"⚪ Pendiente") -> 5 | G47: =COUNTIFS('Mapa de estudio'!$B$2:$B$171,$A47,'Mapa de estudio'!$E$2:$E$171,"🔴 Débil") -> 0 | H47: =IFERROR(C47/B47,0) -> 0.33333333 | J47: ='Mapa de estudio'!A68 -> 3.2 | K47: =LEFT(J47,FIND(".",J47)-1) -> 3 | L47: ='Mapa de estudio'!C68 -> Inferencia | M47: ='Mapa de estudio'!E68 -> 🟢 Comprendido | N47: ='Mapa de estudio'!H68 -> Baja
A48: 5. CLIPS / FuzzyCLIPS | B48: =COUNTIF('Mapa de estudio'!$B$2:$B$171,$A48) -> 52 | C48: =COUNTIFS('Mapa de estudio'!$B$2:$B$171,$A48,'Mapa de estudio'!$E$2:$E$171,"🟢 Firme")+COUNTIFS('Mapa de estudio'!$B$2:$B$171,$A48,'Mapa de estudio'!$E$2:$E$171,"🟢 Comprendido") -> 25 | D48: =COUNTIFS('Mapa de estudio'!$B$2:$B$171,$A48,'Mapa de estudio'!$E$2:$E$171,"🟠 Iniciado")+COUNTIFS('Mapa de estudio'!$B$2:$B$171,$A48,'Mapa de estudio'!$E$2:$E$171,"🟠 Parcial") -> 4 | E48: =COUNTIFS('Mapa de estudio'!$B$2:$B$171,$A48,'Mapa de estudio'!$E$2:$E$171,"🟡 Repasar") -> 4 | F48: =COUNTIFS('Mapa de estudio'!$B$2:$B$171,$A48,'Mapa de estudio'!$E$2:$E$171,"⚪ Pendiente") -> 18 | G48: =COUNTIFS('Mapa de estudio'!$B$2:$B$171,$A48,'Mapa de estudio'!$E$2:$E$171,"🔴 Débil") -> 1 | H48: =IFERROR(C48/B48,0) -> 0.48076923 | J48: ='Mapa de estudio'!A73 -> 3.3 | K48: =LEFT(J48,FIND(".",J48)-1) -> 3 | L48: ='Mapa de estudio'!C73 -> Inferencia vs. aprendizaje | M48: ='Mapa de estudio'!E73 -> 🟢 Firme | N48: ='Mapa de estudio'!H73 -> Baja
A49: TOTAL CURSO | B49: =SUM(B44:B48) -> 170 | C49: =SUM(C44:C48) -> 100 | D49: =SUM(D44:D48) -> 10 | E49: =SUM(E44:E48) -> 35 | F49: =SUM(F44:F48) -> 23 | G49: =SUM(G44:G48) -> 2 | H49: =IFERROR(C49/B49,0) -> 0.58823529 | J49: ='Mapa de estudio'!A76 -> 3.4 | K49: =LEFT(J49,FIND(".",J49)-1) -> 3 | L49: ='Mapa de estudio'!C76 -> Reglas lingüísticas | M49: ='Mapa de estudio'!E76 -> 🟢 Firme | N49: ='Mapa de estudio'!H76 -> Media
...

Sheet Mapa de estudio
A1: Código | B1: Bloque | C1: Tema / concepto | D1: Nivel | E1: Estado | F1: Qué significa / evidencia actual | G1: Siguiente paso | H1: Prioridad | I1: Actualizado | J1: Fuente
A2: 1 | B2: 1. Modelos clásicos de incertidumbre | C2: MODELOS CLÁSICOS DE INCERTIDUMBRE | D2: 0 | E2: 🟢 Comprendido | F2: Formas clásicas de manejar la duda: Bayes, Factores de Certeza y Dempster-Shafer. | G2: Completar Bayes y continuar con CF y Dempster-Shafer. | H2: Alta | I2: 13/09/2026 | J2: Mapa de estudio + resumen teórico
A3: 1.1 | B3: 1. Modelos clásicos de incertidumbre | C3: Qué es incertidumbre | D3: 1 | E3: 🟢 Comprendido | F3: Conceptualmente, es no tener información suficiente para saber con seguridad si algo es verdad. Ej: no sé si mi amigo llegará tarde; solo veo el tráfico. | H3: Baja | I3: 13/09/2026 | J3: Mapa de estudio + resumen teórico
A4: 1.1.a | B4: 1. Modelos clásicos de incertidumbre | C4: Información parcial / incompleta | D4: 2 | E4: 🟢 Comprendido | F4: Conceptualmente, es una causa de la incertidumbre: faltan datos, así que no puedo estar seguro de la conclusión. | H4: Baja | I4: 13/09/2026 | J4: Mapa de estudio + resumen teórico
A5: 1.1.b | B5: 1. Modelos clásicos de incertidumbre | C5: Duda sobre el hecho | D5: 2 | E5: 🟢 Comprendido | F5: Conceptualmente, es dudar del hecho mismo: no sé si es verdadero, falso o si la fuente es confiable. | H5: Baja | I5: 13/09/2026 | J5: Mapa de estudio + resumen teórico
A6: 1.1.c | B6: 1. Modelos clásicos de incertidumbre | C6: Idea clave | D6: 2 | E6: 🟢 Comprendido | F6: Conceptualmente, es la frase que resume la incertidumbre: «no sé con suficiente certeza qué ocurre». | H6: Baja | I6: 13/09/2026 | J6: Mapa de estudio + resumen teórico
A7: 1.2 | B7: 1. Modelos clásicos de incertidumbre | C7: Incertidumbre vs. borrosidad | D7: 1 | E7: 🟢 Firme | F7: Conceptualmente, son dos problemas distintos: en la incertidumbre dudo si el hecho es verdad; en la borrosidad conozco el hecho, pero la categoría es gradual. | H7: Baja | I7: 13/09/2026 | J7: Mapa de estudio + resumen teórico
A8: 1.2.a | B8: 1. Modelos clásicos de incertidumbre | C8: Incertidumbre | D8: 2 | E8: 🟢 Firme | F8: Conceptualmente, es dudar de si el hecho es verdad. Ej: ¿lloverá mañana? | H8: Baja | I8: 13/09/2026 | J8: Mapa de estudio + resumen teórico
A9: 1.2.b | B9: 1. Modelos clásicos de incertidumbre | C9: Borrosidad | D9: 2 | E9: 🟢 Firme | F9: Conceptualmente, es conocer bien el dato pero que su categoría no tenga una frontera exacta. Ej: mide 1.75 m; ¿cuenta como «alto»? | H9: Baja | I9: 13/09/2026 | J9: Mapa de estudio + resumen teórico
A10: 1.3 | B10: 1. Modelos clásicos de incertidumbre | C10: Probabilidad Bayesiana | D10: 1 | E10: 🟢 Comprendido | F10: Conceptualmente, es un método para actualizar lo que creo sobre una hipótesis cuando aparece evidencia nueva: creencia inicial → evidencia → creencia nueva. | G10: Seguir con P(e|h), P(e) y recién después construir el Teorema de Bayes. | H10: Alta | I10: 13/09/2026 | J10: Resumen teórico: Probabilidad Bayesiana
A11: 1.3.a | B11: 1. Modelos clásicos de incertidumbre | C11: h = hipótesis | D11: 2 | E11: 🟢 Comprendido | F11: Conceptualmente, es la afirmación que quiero comprobar. Ej: «quien llama es mi amigo». | H11: Baja | I11: 13/09/2026 | J11: Sesión 13/09/2026
A12: 1.3.b | B12: 1. Modelos clásicos de incertidumbre | C12: e = evidencia | D12: 2 | E12: 🟢 Comprendido | F12: Conceptualmente, es el dato nuevo que observo y que puede cambiar lo que creo sobre h. Ej: «se oye tráfico». | H12: Baja | I12: 13/09/2026 | J12: Sesión 13/09/2026
A13: 1.3.c | B13: 1. Modelos clásicos de incertidumbre | C13: P(h) = probabilidad previa | D13: 2 | E13: 🟢 Comprendido | F13: Conceptualmente, es cuánto creo en h antes de ver la evidencia e. | H13: Baja | I13: 13/09/2026 | J13: Sesión 13/09/2026
A14: 1.3.d | B14: 1. Modelos clásicos de incertidumbre | C14: P(h|e) = probabilidad posterior | D14: 2 | E14: 🟢 Comprendido | F14: Conceptualmente, es cuánto creo en h después de ver e (la barra «|» se lee «dado que»). | H14: Baja | I14: 13/09/2026 | J14: Sesión 13/09/2026
A15: 1.3.e | B15: 1. Modelos clásicos de incertidumbre | C15: Relación previa → evidencia → posterior | D15: 2 | E15: 🟢 Comprendido | F15: Conceptualmente, es el recorrido de mi creencia: parto de P(h), llega e y obtengo P(h|e). | H15: Baja | I15: 13/09/2026 | J15: Verificación oral 13/09/2026
A16: 1.3.f | B16: 1. Modelos clásicos de incertidumbre | C16: P(e|h) = verosimilitud | D16: 2 | E16: 🟢 Comprendido | F16: Conceptualmente, es qué tan esperable sería ver la evidencia e si la hipótesis h fuera cierta. Ej: si llama mi amigo de la calle, oír tráfico es muy esperable. | G16: Explicarlo antes de usar la fórmula. | H16: Alta | I16: 13/09/2026 | J16: Resumen teórico: Probabilidad Bayesiana
A17: 1.3.g | B17: 1. Modelos clásicos de incertidumbre | C17: P(e) = probabilidad de la evidencia | D17: 2 | E17: 🟢 Comprendido | F17: Conceptualmente, es qué tan común es ver la evidencia e en total (con h y sin h); sirve de divisor para que el resultado quede entre 0 y 1. | G17: Explicarlo junto con P(e|h) sin mezclar ambos. | H17: Alta | I17: 13/09/2026 | J17: Resumen teórico: Probabilidad Bayesiana
A18: 1.3.h | B18: 1. Modelos clásicos de incertidumbre | C18: Teorema de Bayes | D18: 2 | E18: 🟢 Comprendido | F18: Conceptualmente, es la regla que calcula la creencia nueva: mi creencia inicial ajustada por qué tan esperable era la evidencia, dividida entre qué tan común es esa evidencia. Fórmula: P(h|e) = P(h)·P(e|h) / P(e). | G18: Construir la fórmula solo cuando cada término esté entendido. | H18: Alta | I18: 13/09/2026 | J18: Resumen teórico: Probabilidad Bayesiana
A19: 1.3.i | B19: 1. Modelos clásicos de incertidumbre | C19: Ejemplo con una evidencia | D19: 2 | E19: 🟢 Comprendido | F19: Conceptualmente, es usar la fórmula de Bayes con números para ver cuánto cambia mi creencia en h cuando llega e. Cómo: P(h|e) = P(h)·P(e|h) / P(e). Ej (M = meningitis, S = síntoma): P(S|M)=0.5, P(M)=1/50.000, P(S)=1/20 → P(M|S) = 0.5·(1/50.000) / (1/20) = 0.0002. | G19: Resolver paso a paso. | H19: Alta | I19: 13/09/2026 | J19: Mapa de estudio + resumen teórico
A20: 1.3.j | B20: 1. Modelos clásicos de incertidumbre | C20: Múltiples evidencias | D20: 2 | E20: 🟢 Comprendido | F20: Conceptualmente, es hacer lo mismo con varias evidencias: cada una vuelve a mover la creencia y se combinan todas. Cómo: por cada hipótesis multiplico su P(h) por la P(e|h) de cada evidencia, y divido entre la suma de todas las hipótesis. Ej: h1 = inversor de alto riesgo, h2 = de bajo riesgo; P(h1)=0.3, P(h2)=0.7. e1 = soltero: P(e1|h1)=0.6, P(e1|h2)=0.4. e2 = ingresos altos: P(e2|h1)=0.2, P(e2|h2)=0.8. h1: 0.3·0.6·0.2 = 0.036; h2: 0.7·0.4·0.8 = 0.224 → P(h1|e1,e2) = 0.036 / (0.036+0.224) ≈ 0.14. | G20: Ver después de dominar Bayes básico. | H20: Media | I20: 13/09/2026 | J20: Resumen teórico: Probabilidad Bayesiana
A21: 1.3.k | B21: 1. Modelos clásicos de incertidumbre | C21: Hipótesis exclusivas y exhaustivas | D21: 2 | E21: 🟢 Comprendido | F21: Conceptualmente, es exigir que las hipótesis sean exclusivas (solo una es cierta) y exhaustivas (no falta ninguna), para que sus probabilidades sumen 1. | G21: Introducir al estudiar múltiples evidencias. | H21: Media | I21: 13/09/2026 | J21: Mapa de estudio + resumen teórico
A22: 1.3.l | B22: 1. Modelos clásicos de incertidumbre | C22: Limitaciones del enfoque probabilista | D22: 2 | E22: 🟢 Comprendido | F22: Conceptualmente, son los límites de Bayes: necesita muchas probabilidades, muestras representativas e independencia, y obliga a que P(h)+P(no h)=1. | G22: Revisar al cerrar Bayes. | H22: Media | I22: 13/09/2026 | J22: Resumen teórico: Probabilidad Bayesiana
A23: 1.4 | B23: 1. Modelos clásicos de incertidumbre | C23: Factores de Certeza / MYCIN | D23: 1 | E23: 🟠 Iniciado | F23: Conceptualmente, es un número entre -1 y 1 que dice cuánta confianza tengo en un hecho o regla, según un experto (1 = seguro que sí, -1 = seguro que no). | G23: Retomar después de Bayes. | H23: Alta | I23: 13/09/2026 | J23: Mapa de estudio + resumen teórico
A24: 1.4.a | B24: 1. Modelos clásicos de incertidumbre | C24: Concepto de CF | D24: 2 | E24: 🟢 Comprendido | F24: Conceptualmente, es un número que dice cuánta confianza tengo en un hecho o regla, según el juicio de un experto. | H24: Baja | I24: 13/09/2026 | J24: Mapa de estudio + resumen teórico
A25: 1.4.b | B25: 1. Modelos clásicos de incertidumbre | C25: Confianza expresada numéricamente | D25: 2 | E25: 🟢 Comprendido | F25: Conceptualmente, es una escala de -1 a 1: 1 = seguro que sí, 0 = sin información, -1 = seguro que no. | H25: Baja | I25: 13/09/2026 | J25: Mapa de estudio + resumen teórico
A26: 1.4.c | B26: 1. Modelos clásicos de incertidumbre | C26: Combinación de CF positivos | D26: 2 | E26: 🟢 Comprendido | F26: Conceptualmente, es una regla que refuerza mi confianza cuando dos pistas apuntan a la misma conclusión. Cómo: CF1 + CF2·(1−CF1). Ej: «viernes → tráfico» 0.8 y «llueve → tráfico» 0.7 → 0.8 + 0.7·(1−0.8) = 0.94. | H26: Alta | I26: 13/09/2026 | J26: Mapa de estudio + resumen teórico
A27: 1.4.d | B27: 1. Modelos clásicos de incertidumbre | C27: Combinación de CF negativos | D27: 2 | E27: 🟢 Comprendido | F27: Conceptualmente, es una regla que refuerza mi desconfianza cuando dos pistas apuntan en contra. Cómo: CF1 + CF2·(1+CF1). Ej: CF1 = -0.3 y CF2 = -0.4 → -0.3 + (-0.4)·(1−0.3) = -0.58. | H27: Alta | I27: 13/09/2026 | J27: Mapa de estudio + resumen teórico
A28: 1.4.e | B28: 1. Modelos clásicos de incertidumbre | C28: Evidencias contradictorias | D28: 2 | E28: 🟢 Comprendido | F28: Conceptualmente, es una regla que compensa una pista a favor con otra en contra. Cómo: (CF1+CF2) / (1 − menor valor absoluto). Ej: 0.8 y -0.4 → (0.8−0.4) / (1−0.4) = 0.4/0.6 ≈ 0.67. | H28: Alta | I28: 13/09/2026 | J28: Mapa de estudio + resumen teórico
A29: 1.4.f | B29: 1. Modelos clásicos de incertidumbre | C29: AND → mínimo | D29: 2 | E29: 🟢 Comprendido | F29: Conceptualmente, es una regla que dice que con «A y B» la confianza es la del dato más débil. Cómo: menor CF de las condiciones × CF de la regla. Ej: CF(A)=0.7 y CF(B)=0.2, regla 0.8 → min = 0.2 → 0.2·0.8 = 0.16. | H29: Alta | I29: 13/09/2026 | J29: Mapa de estudio + resumen teórico
A30: 1.4.g | B30: 1. Modelos clásicos de incertidumbre | C30: OR → máximo | D30: 2 | E30: 🟢 Comprendido | F30: Conceptualmente, es una regla que dice que con «A o B» basta el dato más confiable. Cómo: mayor CF de las condiciones × CF de la regla. Ej: CF(D)=0.3 y CF(F)=0.6, regla 0.4 → max = 0.6 → 0.6·0.4 = 0.24. | H30: Alta | I30: 13/09/2026 | J30: Mapa de estudio + resumen teórico
A31: 1.4.h | B31: 1. Modelos clásicos de incertidumbre | C31: Encadenamiento de reglas | D31: 2 | E31: 🟢 Comprendido | F31: Conceptualmente, es pasar la confianza de una regla a la siguiente: la conclusión de una sirve de dato para la otra. Cómo: se multiplica en cada regla. Ej: si la conclusión intermedia h quedó con CF 0.17 y la regla h→g tiene CF -0.7 → CF(g) = 0.17·(-0.7) ≈ -0.12. | H31: Alta | I31: 13/09/2026 | J31: Mapa de estudio + resumen teórico
A32: 1.5 | B32: 1. Modelos clásicos de incertidumbre | C32: Dempster-Shafer | D32: 1 | E32: 🟢 Comprendido | F32: Conceptualmente, es una teoría que me deja no elegir una sola hipótesis: reparto mi creencia entre grupos de hipótesis o la dejo sin asignar («no sé»). | G32: Ver después de Factores de Certeza. | H32: Alta | I32: 13/09/2026 | J32: Mapa de estudio + resumen teórico
A33: 1.5.a | B33: 1. Modelos clásicos de incertidumbre | C33: Marco de discernimiento | D33: 2 | E33: 🟢 Comprendido | F33: Conceptualmente, es la lista de todas las respuestas posibles, de las que solo una es la cierta. Ej: {Bob, Jim, Sally}. | H33: Alta | I33: 13/09/2026 | J33: Mapa de estudio + resumen teórico
A34: 1.5.b | B34: 1. Modelos clásicos de incertidumbre | C34: Masa m | D34: 2 | E34: 🟢 Comprendido | F34: Conceptualmente, es una regla que reparte mi creencia total (que suma 1) entre grupos de hipótesis, sin partirla dentro de cada grupo. Ej: m({Bob})=0.3, m({Bob,Jim})=0.2, m(H)=0.5 (no sé). | H34: Alta | I34: 13/09/2026 | J34: Mapa de estudio + resumen teórico
A35: 1.5.c | B35: 1. Modelos clásicos de incertidumbre | C35: Creencia BEL | D35: 2 | E35: 🟢 Comprendido | F35: Conceptualmente, es lo mínimo que la evidencia ya garantiza a favor de una proposición S. Cómo: suma de masas de los grupos que caen dentro de S. Ej: con m({Bob})=0.3, m({Bob,Jim})=0.2, m(H)=0.5 (los demás grupos valen 0): BEL({Bob}) = 0.3; BEL({Bob,Jim}) = 0.3+0.2 = 0.5. | H35: Alta | I35: 13/09/2026 | J35: Mapa de estudio + resumen teórico
A36: 1.5.d | B36: 1. Modelos clásicos de incertidumbre | C36: Plausibilidad PL | D36: 2 | E36: 🟢 Comprendido | F36: Conceptualmente, es lo máximo que la evidencia todavía permite a favor de una proposición S (lo que nadie descarta). Cómo: suma de masas de los grupos que comparten alguna hipótesis con S. Ej: con las mismas masas: PL({Bob}) = 0.3+0.2+0.5 = 1; PL({Jim}) = 0.2+0.5 = 0.7. | H36: Alta | I36: 13/09/2026 | J36: Mapa de estudio + resumen teórico
A37: 1.5.e | B37: 1. Modelos clásicos de incertidumbre | C37: Intervalo de creencia | D37: 2 | E37: 🟢 Comprendido | F37: Conceptualmente, es el rango entre lo garantizado (BEL) y lo posible (PL) para decir cuánta duda queda. Ej: con m({Bob})=0.3, m({Bob,Jim})=0.2, m(H)=0.5: Bob → [0.3, 1]; el ancho (1−0.3 = 0.7) es la duda que queda. | H37: Alta | I37: 13/09/2026 | J37: Mapa de estudio + resumen teórico
A38: 1.5.f | B38: 1. Modelos clásicos de incertidumbre | C38: Combinación de evidencias | D38: 2 | E38: 🟡 Repasar | F38: Conceptualmente, es una regla que mezcla dos fuentes de evidencia en una sola, quitando lo que se contradice. Cómo: multiplico cada masa de la fuente 1 por cada masa de la fuente 2. Si los dos grupos no comparten ninguna hipótesis, ese producto es CONFLICTO; los demás se suman por el grupo que tienen en común, y todo se divide entre 1 − conflicto. Ej (H = {Bob, Jim, Sally}): fuente 1: m1({Bob})=0.3, m1({Bob,Jim})=0.2, m1(H)=0.5. Fuente 2: m2({Jim})=0.6, m2(H)=0.4. Conflicto: {Bob} y {Jim} no comparten nada → 0.3·0.6 = 0.18. m3({Bob}) = (m1({Bob})·m2(H)) / (1−0.18) = 0.12/0.82 ≈ 0.146. | H38: Alta | I38: 13/09/2026 | J38: Mapa de estudio + resumen teórico
A39: 2 | B39: 2. Fundamentos de lógica borrosa | C39: FUNDAMENTOS DE LÓGICA BORROSA | D39: 0 | E39: 🟠 Iniciado | F39: Conjuntos con grados de pertenencia y sus operaciones: conjuntos borrosos, operadores y relaciones. | G39: Continuar cuando corresponda al orden del curso. | H39: Alta | I39: 13/09/2026 | J39: Mapa de estudio + resumen teórico
A40: 2.1 | B40: 2. Fundamentos de lógica borrosa | C40: Qué problema resuelve | D40: 1 | E40: 🟢 Comprendido | F40: Conceptualmente, sirve para trabajar con categorías sin frontera exacta (alto, joven) cuando el dato sí lo conozco. | H40: Baja | I40: 13/09/2026 | J40: Mapa de estudio + resumen teórico
...

Sheet Bayes 1.3
A1: Código | B1: Concepto | C1: Estado | D1: Qué ya comprendes | E1: Qué falta / siguiente paso | F1: Prioridad
A2: 1.3 | B2: Probabilidad Bayesiana | C2: =INDEX('Mapa de estudio'!$E$2:$E$171,MATCH($A2,'Mapa de estudio'!$A$2:$A$171,0)) -> 🟢 Comprendido | D2: =INDEX('Mapa de estudio'!$F$2:$F$171,MATCH($A2,'Mapa de estudio'!$A$2:$A$171,0))&"" -> Conceptualmente, es un método para actualizar lo que creo sobre una hipótesis cuando aparece evidencia nueva: creencia inicial → evidencia → creencia nueva. | E2: =INDEX('Mapa de estudio'!$G$2:$G$171,MATCH($A2,'Mapa de estudio'!$A$2:$A$171,0))&"" -> Seguir con P(e|h), P(e) y recién después construir el Teorema de Bayes. | F2: =INDEX('Mapa de estudio'!$H$2:$H$171,MATCH($A2,'Mapa de estudio'!$A$2:$A$171,0)) -> Alta
A3: 1.3.a | B3: h = hipótesis | C3: =INDEX('Mapa de estudio'!$E$2:$E$171,MATCH($A3,'Mapa de estudio'!$A$2:$A$171,0)) -> 🟢 Comprendido | D3: =INDEX('Mapa de estudio'!$F$2:$F$171,MATCH($A3,'Mapa de estudio'!$A$2:$A$171,0))&"" -> Conceptualmente, es la afirmación que quiero comprobar. Ej: «quien llama es mi amigo». | E3: =INDEX('Mapa de estudio'!$G$2:$G$171,MATCH($A3,'Mapa de estudio'!$A$2:$A$171,0))&"" | F3: =INDEX('Mapa de estudio'!$H$2:$H$171,MATCH($A3,'Mapa de estudio'!$A$2:$A$171,0)) -> Baja
A4: 1.3.b | B4: e = evidencia | C4: =INDEX('Mapa de estudio'!$E$2:$E$171,MATCH($A4,'Mapa de estudio'!$A$2:$A$171,0)) -> 🟢 Comprendido | D4: =INDEX('Mapa de estudio'!$F$2:$F$171,MATCH($A4,'Mapa de estudio'!$A$2:$A$171,0))&"" -> Conceptualmente, es el dato nuevo que observo y que puede cambiar lo que creo sobre h. Ej: «se oye tráfico». | E4: =INDEX('Mapa de estudio'!$G$2:$G$171,MATCH($A4,'Mapa de estudio'!$A$2:$A$171,0))&"" | F4: =INDEX('Mapa de estudio'!$H$2:$H$171,MATCH($A4,'Mapa de estudio'!$A$2:$A$171,0)) -> Baja
A5: 1.3.c | B5: P(h) = probabilidad previa | C5: =INDEX('Mapa de estudio'!$E$2:$E$171,MATCH($A5,'Mapa de estudio'!$A$2:$A$171,0)) -> 🟢 Comprendido | D5: =INDEX('Mapa de estudio'!$F$2:$F$171,MATCH($A5,'Mapa de estudio'!$A$2:$A$171,0))&"" -> Conceptualmente, es cuánto creo en h antes de ver la evidencia e. | E5: =INDEX('Mapa de estudio'!$G$2:$G$171,MATCH($A5,'Mapa de estudio'!$A$2:$A$171,0))&"" | F5: =INDEX('Mapa de estudio'!$H$2:$H$171,MATCH($A5,'Mapa de estudio'!$A$2:$A$171,0)) -> Baja
A6: 1.3.d | B6: P(h|e) = probabilidad posterior | C6: =INDEX('Mapa de estudio'!$E$2:$E$171,MATCH($A6,'Mapa de estudio'!$A$2:$A$171,0)) -> 🟢 Comprendido | D6: =INDEX('Mapa de estudio'!$F$2:$F$171,MATCH($A6,'Mapa de estudio'!$A$2:$A$171,0))&"" -> Conceptualmente, es cuánto creo en h después de ver e (la barra «|» se lee «dado que»). | E6: =INDEX('Mapa de estudio'!$G$2:$G$171,MATCH($A6,'Mapa de estudio'!$A$2:$A$171,0))&"" | F6: =INDEX('Mapa de estudio'!$H$2:$H$171,MATCH($A6,'Mapa de estudio'!$A$2:$A$171,0)) -> Baja
A7: 1.3.e | B7: Relación previa → evidencia → posterior | C7: =INDEX('Mapa de estudio'!$E$2:$E$171,MATCH($A7,'Mapa de estudio'!$A$2:$A$171,0)) -> 🟢 Comprendido | D7: =INDEX('Mapa de estudio'!$F$2:$F$171,MATCH($A7,'Mapa de estudio'!$A$2:$A$171,0))&"" -> Conceptualmente, es el recorrido de mi creencia: parto de P(h), llega e y obtengo P(h|e). | E7: =INDEX('Mapa de estudio'!$G$2:$G$171,MATCH($A7,'Mapa de estudio'!$A$2:$A$171,0))&"" | F7: =INDEX('Mapa de estudio'!$H$2:$H$171,MATCH($A7,'Mapa de estudio'!$A$2:$A$171,0)) -> Baja
A8: 1.3.f | B8: P(e|h) = verosimilitud | C8: =INDEX('Mapa de estudio'!$E$2:$E$171,MATCH($A8,'Mapa de estudio'!$A$2:$A$171,0)) -> 🟢 Comprendido | D8: =INDEX('Mapa de estudio'!$F$2:$F$171,MATCH($A8,'Mapa de estudio'!$A$2:$A$171,0))&"" -> Conceptualmente, es qué tan esperable sería ver la evidencia e si la hipótesis h fuera cierta. Ej: si llama mi amigo de la calle, oír tráfico es muy esperable. | E8: =INDEX('Mapa de estudio'!$G$2:$G$171,MATCH($A8,'Mapa de estudio'!$A$2:$A$171,0))&"" -> Explicarlo antes de usar la fórmula. | F8: =INDEX('Mapa de estudio'!$H$2:$H$171,MATCH($A8,'Mapa de estudio'!$A$2:$A$171,0)) -> Alta
A9: 1.3.g | B9: P(e) = probabilidad de la evidencia | C9: =INDEX('Mapa de estudio'!$E$2:$E$171,MATCH($A9,'Mapa de estudio'!$A$2:$A$171,0)) -> 🟢 Comprendido | D9: =INDEX('Mapa de estudio'!$F$2:$F$171,MATCH($A9,'Mapa de estudio'!$A$2:$A$171,0))&"" -> Conceptualmente, es qué tan común es ver la evidencia e en total (con h y sin h); sirve de divisor para que el resultado quede entre 0 y 1. | E9: =INDEX('Mapa de estudio'!$G$2:$G$171,MATCH($A9,'Mapa de estudio'!$A$2:$A$171,0))&"" -> Explicarlo junto con P(e|h) sin mezclar ambos. | F9: =INDEX('Mapa de estudio'!$H$2:$H$171,MATCH($A9,'Mapa de estudio'!$A$2:$A$171,0)) -> Alta
A10: 1.3.h | B10: Teorema de Bayes | C10: =INDEX('Mapa de estudio'!$E$2:$E$171,MATCH($A10,'Mapa de estudio'!$A$2:$A$171,0)) -> 🟢 Comprendido | D10: =INDEX('Mapa de estudio'!$F$2:$F$171,MATCH($A10,'Mapa de estudio'!$A$2:$A$171,0))&"" -> Conceptualmente, es la regla que calcula la creencia nueva: mi creencia inicial ajustada por qué tan esperable era la evidencia, dividida entre qué tan común es esa evidencia. Fórmula: P(h|e) = P(h)·P(e|h) / P(e). | E10: =INDEX('Mapa de estudio'!$G$2:$G$171,MATCH($A10,'Mapa de estudio'!$A$2:$A$171,0))&"" -> Construir la fórmula solo cuando cada término esté entendido. | F10: =INDEX('Mapa de estudio'!$H$2:$H$171,MATCH($A10,'Mapa de estudio'!$A$2:$A$171,0)) -> Alta
A11: 1.3.i | B11: Ejemplo con una evidencia | C11: =INDEX('Mapa de estudio'!$E$2:$E$171,MATCH($A11,'Mapa de estudio'!$A$2:$A$171,0)) -> 🟢 Comprendido | D11: =INDEX('Mapa de estudio'!$F$2:$F$171,MATCH($A11,'Mapa de estudio'!$A$2:$A$171,0))&"" -> Conceptualmente, es usar la fórmula de Bayes con números para ver cuánto cambia mi creencia en h cuando llega e. Cómo: P(h|e) = P(h)·P(e|h) / P(e). Ej (M = meningitis, S = síntoma): P(S|M)=0.5, P(M)=1/50.000, P(S)=1/20 → P(M|S) = 0.5·(1/50.000) / (1/20) = 0.0002. | E11: =INDEX('Mapa de estudio'!$G$2:$G$171,MATCH($A11,'Mapa de estudio'!$A$2:$A$171,0))&"" -> Resolver paso a paso. | F11: =INDEX('Mapa de estudio'!$H$2:$H$171,MATCH($A11,'Mapa de estudio'!$A$2:$A$171,0)) -> Alta
A12: 1.3.j | B12: Múltiples evidencias | C12: =INDEX('Mapa de estudio'!$E$2:$E$171,MATCH($A12,'Mapa de estudio'!$A$2:$A$171,0)) -> 🟢 Comprendido | D12: =INDEX('Mapa de estudio'!$F$2:$F$171,MATCH($A12,'Mapa de estudio'!$A$2:$A$171,0))&"" -> Conceptualmente, es hacer lo mismo con varias evidencias: cada una vuelve a mover la creencia y se combinan todas. Cómo: por cada hipótesis multiplico su P(h) por la P(e|h) de cada evidencia, y divido entre la suma de todas las hipótesis. Ej: h1 = inversor de alto riesgo, h2 = de bajo riesgo; P(h1)=0.3, P(h2)=0.7. e1 = soltero: P(e1|h1)=0.6, P(e1|h2)=0.4. e2 = ingresos altos: P(e2|h1)=0.2, P(e2|h2)=0.8. h1: 0.3·0.6·0.2 = 0.036; h2: 0.7·0.4·0.8 = 0.224 → P(h1|e1,e2) = 0.036 / (0.036+0.224) ≈ 0.14. | E12: =INDEX('Mapa de estudio'!$G$2:$G$171,MATCH($A12,'Mapa de estudio'!$A$2:$A$171,0))&"" -> Ver después de dominar Bayes básico. | F12: =INDEX('Mapa de estudio'!$H$2:$H$171,MATCH($A12,'Mapa de estudio'!$A$2:$A$171,0)) -> Media
A13: 1.3.k | B13: Hipótesis exclusivas y exhaustivas | C13: =INDEX('Mapa de estudio'!$E$2:$E$171,MATCH($A13,'Mapa de estudio'!$A$2:$A$171,0)) -> 🟢 Comprendido | D13: =INDEX('Mapa de estudio'!$F$2:$F$171,MATCH($A13,'Mapa de estudio'!$A$2:$A$171,0))&"" -> Conceptualmente, es exigir que las hipótesis sean exclusivas (solo una es cierta) y exhaustivas (no falta ninguna), para que sus probabilidades sumen 1. | E13: =INDEX('Mapa de estudio'!$G$2:$G$171,MATCH($A13,'Mapa de estudio'!$A$2:$A$171,0))&"" -> Introducir al estudiar múltiples evidencias. | F13: =INDEX('Mapa de estudio'!$H$2:$H$171,MATCH($A13,'Mapa de estudio'!$A$2:$A$171,0)) -> Media
A14: 1.3.l | B14: Limitaciones del enfoque probabilista | C14: =INDEX('Mapa de estudio'!$E$2:$E$171,MATCH($A14,'Mapa de estudio'!$A$2:$A$171,0)) -> 🟢 Comprendido | D14: =INDEX('Mapa de estudio'!$F$2:$F$171,MATCH($A14,'Mapa de estudio'!$A$2:$A$171,0))&"" -> Conceptualmente, son los límites de Bayes: necesita muchas probabilidades, muestras representativas e independencia, y obliga a que P(h)+P(no h)=1. | E14: =INDEX('Mapa de estudio'!$G$2:$G$171,MATCH($A14,'Mapa de estudio'!$A$2:$A$171,0))&"" -> Revisar al cerrar Bayes. | F14: =INDEX('Mapa de estudio'!$H$2:$H$171,MATCH($A14,'Mapa de estudio'!$A$2:$A$171,0)) -> Media

Sheet Estados
A1: Estado | B1: Interpretación | C1: Uso en el seguimiento
A2: 🟢 Firme | B2: Dominado | C2: Puedes explicarlo y usarlo con seguridad; idealmente falta confirmar en problema nuevo si aún no se hizo.
A3: 🟢 Comprendido | B3: Comprensión conceptual | C3: Puedes explicarlo correctamente con tus palabras.
A4: 🟡 Repasar | B4: Entendido pero débil | C4: Necesita otra pasada o práctica para estabilizarlo.
A5: 🟠 Iniciado | B5: En progreso | C5: Ya fue introducido, pero falta matemática, procedimiento o aplicación.
A6: 🟠 Parcial | B6: Avanzado parcialmente | C6: Hay varias piezas comprendidas, pero el bloque aún no está cerrado.
A7: ⚪ Pendiente | B7: No estudiado todavía | C7: Aún no se debe evaluar ni asumir como aprendido.
A8: 🔴 Débil | B8: Punto especialmente débil | C8: Requiere reenseñar el paso exacto y volver a verificar.
